Workbook

Sheet Notes
A1: Positions | B1: Code | C1: S5+ | D1: Place | E1: Qualifying | F1: FastestLap | G1: Points
A2: 21 | B2: DNF | C2: 23
A3: 22 | B3: DNS | C3: 24
A4: 23 | B4: DSQ | C4: 25
D10: Miami OG | E10: Miami Updated
A11: Alpine | B11: Joshua | C11: JoshuaRosario89 | D11: 4 | E11: 3
A12: Alpine | B12: Eddie | C12: penguin2780 | E12: 22
A13: McLaren | B13: Nick | C13: infmsmantis | E13: 1
A14: McLaren | B14: Travis | C14: PrisonMike | D14: 6 | E14: 5
A15: VCARB | B15: Patrick | C15: PKnowlez | E15: 9
A16: VCARB | B16: Josh | C16: JellyWaffles37 | E16: 21
A17: Red Bull | B17: Brently | C17: Brentuar | E17: 2
A18: Red Bull | B18: Matthew | C18: NC_Newman | E18: 21
A19: Aston Martin | B19: Del | C19: DELREAL718 | D19: 7 | E19: 6
A20: Aston Martin | B20: Boz | C20: Bositive | E20: 11
A21: Ferrari | B21: Erick | C21: penguinator2780 | D21: 5 | E21: 4
A22: Ferrari | B22: Leo | C22: LeonelM17 | E22: 10
A23: Mercedes | B23: Jayden | C23: Jvytrbl | D23: 3 | E23: 8
A24: Mercedes | B24: Jairo | C24: JairoFSO | E24: 21

Sheet Scoring
A1: Race | D1: Sprint
A2: 1 | B2: 25 | D2: 1 | E2: 8
A3: 2 | B3: 18 | D3: 2 | E3: 7
A4: 3 | B4: 15 | D4: 3 | E4: 6
A5: 4 | B5: 12 | D5: 4 | E5: 5
A6: 5 | B6: 10 | D6: 5 | E6: 4
A7: 6 | B7: 8 | D7: 6 | E7: 3
A8: 7 | B8: 6 | D8: 7 | E8: 2
A9: 8 | B9: 4 | D9: 8 | E9: 1
A10: 9 | B10: 3 | D10: 9 | E10: 0.5
A11: 10 | B11: 2 | D11: 10 | E11: 0.5
A12: 11 | B12: 1 | D12: 11 | E12: 0.5
A13: 12 | B13: 1 | D13: 12 | E13: 0.5
... A21: 20 | B21: 1 | D21: 20 | E21: 0.5
A22: 21 | B22: 0 | C22: DNF | D22: 21 | E22: 0 | F22: DNF
A23: 22 | B23: 0 | C23: DNS | D23: 22 | E23: 0 | F23: DNS
A24: 23 | B24: 0 | C24: DSQ | D24: 23 | E24: 0 | F24: DSQ

Sheet Season1
A1: Team | B1: Driver | C1: Username | D1: BahrainPlace | E1: BahrainQualifying | F1: BahrainFastestLap | G1: BahrainPoints | H1: JeddahPlace | I1: JeddahQualifying | J1: JeddahFastestLap | K1: JeddahPoints | L1: AustraliaPlace | M1: AustraliaQualifying | N1: AustraliaFastestLap | O1: AustraliaPoints | P1: MiamiPlace | Q1: MiamiQualifying | R1: MiamiFastestLap | S1: MiamiPoints | T1: SpainPlace | U1: SpainQualifying | V1: SpainFastestLap | W1: SpainPoints | X1: CanadaPlace | Y1: CanadaQualifying | Z1: CanadaFastestLap | AA1: CanadaPoints | AB1: AustriaPlace | AC1: AustriaQualifying | AD1: AustriaFastestLap | AE1: AustriaPoints | AF1: SilverstonePlace | AG1: SilverstoneQualifying | AH1: SilverstoneFastestLap | AI1: SilverstonePoints | AJ1: SpaPlace | AK1: SpaQualifying | AL1: SpaFastestLap | AM1: SpaPoints | AN1: ZandvoortPlace | AO1: ZandvoortQualifying | AP1: ZandvoortFastestLap | AQ1: ZandvoortPoints | AR1: MonzaPlace | AS1: MonzaQualifying | AT1: MonzaFastestLap | AU1: MonzaPoints | AV1: SingaporePlace | AW1: SingaporeQualifying | AX1: SingaporeFastestLap | AY1: SingaporePoints | AZ1: SuzukaPlace | BA1: SuzukaQualifying | BB1: SuzukaFastestLap | BC1: SuzukaPoints | BD1: QatarPlace | BE1: QatarQualifying | BF1: QatarFastestLap | BG1: QatarPoints | BH1: COTAPlace | BI1: COTAQualifying | BJ1: COTAFastestLap | BK1: COTAPoints | BL1: MexicoPlace | BM1: MexicoQualifying | BN1: MexicoFastestLap | BO1: MexicoPoints | BP1: BrazilPlace | BQ1: BrazilQualifying | BR1: BrazilFastestLap | BS1: BrazilPoints | BT1: Las VegasPlace | BU1: Las VegasQualifying | BV1: Las VegasFastestLap | BW1: Las VegasPoints | BX1: Abu DhabiPlace | BY1: Abu DhabiQualifying | BZ1: Abu DhabiFastestLap | CA1: Abu DhabiPoints | CB1: Starting
A2: McLaren | B2: Nick | C2: infmsmantis | D2: 1 | E2: 1 | F2: N | G2: 30 | H2: 1 | I2: 1 | J2: Y | K2: 31 | L2: 2 | M2: 1 | N2: Y | O2: 24 | P2: 1 | Q2: 1 | R2: Y | S2: 31 | T2: 1 | U2: 2 | V2: N | W2: 29 | X2: 10 | Y2: 4 | Z2: Y | AA2: 3 | AB2: 1 | AC2: 4 | AD2: N | AE2: 27 | AF2: 2 | AG2: 2 | AH2: N | AI2: 22 | AJ2: 1 | AK2: 1 | AL2: N | AM2: 30 | AN2: 2 | AO2: 2 | AP2: Y | AQ2: 23 | AR2: 21 | AS2: 17 | AT2: N | AU2: 0 | AV2: 8 | AW2: 2 | AX2: N | AY2: 5 | AZ2: 1 | BA2: 1 | BB2: Y | BC2: 31 | BD2: 1 | BE2: 2 | BF2: N | BG2: 29 | BH2: 2 | BI2: 5 | BJ2: Y | BK2: 20 | BL2: 3 | BM2: 6 | BN2: N | BO2: 18 | BP2: 1 | BQ2: 4 | BR2: N | BS2: 27 | BT2: 2 | BU2: 1 | BV2: N | BW2: 23 | BX2: 1 | BY2: 1 | BZ2: Y | CA2: 31 | CB2: 0
A3: McLaren | B3: Travis | C3: ImHuntinWabit | D3: 22 | E3: 22 | F3: N | G3: 0 | H3: 22 | I3: 22 | J3: N | K3: 0 | L3: 9 | M3: 5 | N3: N | O3: 2 | P3: 9 | Q3: 3 | R3: N | S3: 4 | T3: 22 | U3: 22 | V3: N | W3: 0 | X3: 22 | Y3: 22 | Z3: N | AA3: 0 | AB3: 4 | AC3: 6 | AD3: N | AE3: 12 | AF3: 3 | AG3: 1 | AH3: N | AI3: 20 | AJ3: 3 | AK3: 3 | AL3: N | AM3: 18 | AN3: 22 | AO3: 22 | AP3: N | AQ3: 0 | AR3: 4 | AS3: 2 | AT3: N | AU3: 16 | AV3: 22 | AW3: 22 | AX3: N | AY3: 0 | AZ3: 12 | BA3: 5 | BB3: N | BC3: 2 | BD3: 22 | BE3: 22 | BF3: N | BG3: 0 | BH3: 4 | BI3: 1 | BJ3: N | BK3: 15 | BL3: 6 | BM3: 7 | BN3: N | BO3: 8 | BP3: 22 | BQ3: 22 | BR3: N | BS3: 0 | BT3: 22 | BU3: 22 | BV3: N | BW3: 0 | BX3: 22 | BY3: 22 | BZ3: N | CA3: 0 | CB3: 0
A4: Aston Martin | B4: Zane | C4: Tastik45 | D4: 4 | E4: 2 | F4: N | G4: 14 | H4: 12 | I4: 4 | J4: N | K4: 1 | L4: 4 | M4: 3 | N4: N | O4: 13 | P4: 7 | Q4: 4 | R4: N | S4: 8 | T4: 3 | U4: 4 | V4: N | W4: 17 | X4: 21 | Y4: 3 | Z4: N | AA4: 0 | AB4: 2 | AC4: 2 | AD4: N | AE4: 22 | AF4: 4 | AG4: 8 | AH4: N | AI4: 12 | AJ4: 4 | AK4: 6 | AL4: N | AM4: 12 | AN4: 8 | AO4: 1 | AP4: N | AQ4: 5 | AR4: 5 | AS4: 1 | AT4: N | AU4: 13 | AV4: 9 | AW4: 1 | AX4: N | AY4: 5 | AZ4: 10 | BA4: 4 | BB4: N | BC4: 3 | BD4: 3 | BE4: 1 | BF4: N | BG4: 20 | BH4: 1 | BI4: 2 | BJ4: N | BK4: 29 | BL4: 1 | BM4: 1 | BN4: Y | BO4: 31 | BP4: 4 | BQ4: 1 | BR4: N | BS4: 17 | BT4: 9 | BU4: 3 | BV4: N | BW4: 4 | BX4: 5 | BY4: 5 | BZ4: N | CA4: 11 | CB4: 0
A5: Aston Martin | B5: David | C5: KingDavidLivee | D5: 10 | E5: 5 | F5: N | G5: 2 | H5: 9 | I5: 5 | J5: N | K5: 3 | L5: 11 | M5: 4 | N5: N | O5: 2 | P5: 22 | Q5: 22 | R5: N | S5: 0 | T5: 5 | U5: 3 | V5: N | W5: 13 | X5: 12 | Y5: 5 | Z5: N | AA5: 2 | AB5: 11 | AC5: 5 | AD5: N | AE5: 1 | AF5: 21 | AG5: 6 | AH5: N | AI5: 0 | AJ5: 21 | AK5: 7 | AL5: N | AM5: 0 | AN5: 12 | AO5: 12 | AP5: N | AQ5: 1 | AR5: 3 | AS5: 4 | AT5: N | AU5: 17 | AV5: 14 | AW5: 6 | AX5: N | AY5: 1 | AZ5: 9 | BA5: 3 | BB5: N | BC5: 4 | BD5: 5 | BE5: 5 | BF5: N | BG5: 11 | BH5: 6 | BI5: 4 | BJ5: N | BK5: 10 | BL5: 9 | BM5: 3 | BN5: N | BO5: 3 | BP5: 9 | BQ5: 3 | BR5: N | BS5: 3 | BT5: 21 | BU5: 6 | BV5: N | BW5: 0 | BX5: 22 | BY5: 22 | BZ5: N | CA5: 0 | CB5: 0
A6: Mercedes | B6: Erick | C6: penguinator2780 | D6: 7 | E6: 3 | F6: Y | G6: 8 | H6: 2 | I6: 2 | J6: N | K6: 22 | L6: 1 | M6: 2 | N6: N | O6: 29 | P6: 2 | Q6: 2 | R6: N | S6: 22 | T6: 2 | U6: 1 | V6: Y | W6: 24 | X6: 8 | Y6: 1 | Z6: N | AA6: 6 | AB6: 3 | AC6: 1 | AD6: Y | AE6: 21 | AF6: 1 | AG6: 3 | AH6: Y | AI6: 29 | AJ6: 2 | AK6: 2 | AL6: Y | AM6: 24 | AN6: 1 | AO6: 3 | AP6: N | AQ6: 28 | AR6: 2 | AS6: 20 | AT6: Y | AU6: 19 | AV6: 1 | AW6: 4 | AX6: Y | AY6: 28 | AZ6: 2 | BA6: 2 | BB6: N | BC6: 22 | BD6: 2 | BE6: 3 | BF6: Y | BG6: 22 | BH6: 5 | BI6: 6 | BJ6: N | BK6: 12 | BL6: 4 | BM6: 5 | BN6: N | BO6: 13 | BP6: 3 | BQ6: 5 | BR6: Y | BS6: 17 | BT6: 1 | BU6: 2 | BV6: Y | BW6: 30 | BX6: 3 | BY6: 2 | BZ6: N | CA6: 19 | CB6: 0
A7: Mercedes | B7: Marcus | C7: oItsBigM | D7: 14 | E7: 18 | F7: N | G7: 1 | H7: 3 | I7: 3 | J7: N | K7: 18 | L7: 3 | M7: 5 | N7: N | O7: 15 | P7: 3 | Q7: 5 | R7: N | S7: 16 | T7: 4 | U7: 5 | V7: N | W7: 13 | X7: 1 | Y7: 2 | Z7: N | AA7: 29 | AB7: 5 | AC7: 3 | AD7: N | AE7: 11 | AF7: 8 | AG7: 5 | AH7: N | AI7: 5 | AJ7: 9 | AK7: 4 | AL7: N | AM7: 3 | AN7: 21 | AO7: 19 | AP7: N | AQ7: 0 | AR7: 1 | AS7: 3 | AT7: N | AU7: 28 | AV7: 11 | AW7: 3 | AX7: N | AY7: 3 | AZ7: 15 | BA7: 7 | BB7: N | BC7: 1 | BD7: 22 | BE7: 22 | BF7: N | BG7: 0 | BH7: 22 | BI7: 22 | BJ7: N | BK7: 0 | BL7: 5 | BM7: 4 | BN7: N | BO7: 12 | BP7: 14 | BQ7: 6 | BR7: N | BS7: 0 | BT7: 3 | BU7: 5 | BV7: N | BW7: 16 | BX7: 2 | BY7: 4 | BZ7: N | CA7: 20 | CB7: 0
A8: Red Bull | B8: Josh L | C8: WannaGetRowdy | D8: 11 | E8: 4 | F8: N | G8: 2 | H8: 22 | I8: 22 | J8: N | K8: 0 | L8: 22 | M8: 22 | N8: N | O8: 0 | P8: 22 | Q8: 22 | R8: N | S8: 0 | T8: 22 | U8: 22 | V8: N | W8: 0 | X8: 22 | Y8: 22 | Z8: N | AA8: 0 | AB8: 22 | AC8: 22 | AD8: N | AE8: 0 | AF8: 22 | AG8: 22 | AH8: N | AI8: 0 | AJ8: 22 | AK8: 22 | AL8: N | AM8: 0 | AN8: 22 | AO8: 22 | AP8: N | AQ8: 0 | AR8: 22 | AS8: 22 | AT8: N | AU8: 0 | AV8: 22 | AW8: 22 | AX8: N | AY8: 0 | AZ8: 22 | BA8: 22 | BB8: N | BC8: 0 | BD8: 22 | BE8: 22 | BF8: N | BG8: 0 | BH8: 22 | BI8: 22 | BJ8: N | BK8: 0 | BL8: 22 | BM8: 22 | BN8: N | BO8: 0 | BP8: 22 | BQ8: 22 | BR8: N | BS8: 0 | BT8: 22 | BU8: 22 | BV8: N | BW8: 0 | BX8: 22 | BY8: 22 | BZ8: N | CA8: 0 | CB8: 0
A9: Red Bull | B9: Boz | C9: Bositive | D9: 13 | E9: 10 | F9: N | G9: 1 | H9: 22 | I9: 22 | J9: N | K9: 0 | L9: 22 | M9: 22 | N9: N | O9: 0 | P9: 4 | Q9: 6 | R9: N | S9: 12 | T9: 10 | U9: 6 | V9: N | W9: 1 | X9: 14 | Y9: 7 | Z9: N | AA9: 1 | AB9: 6 | AC9: 7 | AD9: N | AE9: 10 | AF9: 5 | AG9: 4 | AH9: N | AI9: 12 | AJ9: 12 | AK9: 5 | AL9: N | AM9: 1 | AN9: 10 | AO9: 18 | AP9: N | AQ9: 2 | AR9: 6 | AS9: 5 | AT9: N | AU9: 11 | AV9: 15 | AW9: 5 | AX9: N | AY9: 1 | AZ9: 14 | BA9: 6 | BB9: N | BC9: 1 | BD9: 4 | BE9: 4 | BF9: N | BG9: 14 | BH9: 3 | BI9: 3 | BJ9: N | BK9: 18 | BL9: 2 | BM9: 2 | BN9: N | BO9: 19 | BP9: 2 | BQ9: 2 | BR9: N | BS9: 22 | BT9: 4 | BU9: 4 | BV9: N | BW9: 14 | BX9: 4 | BY9: 3 | BZ9: N | CA9: 15 | CB9: 0
A10: Ferrari | B10: Gary | C10: Mediummnh | D10: 22 | E10: 22 | F10: N | G10: 0 | H10: 22 | I10: 22 | J10: N | K10: 0 | L10: 22 | M10: 22 | N10: N | O10: 0 | P10: 22 | Q10: 22 | R10: N | S10: 0 | T10: 22 | U10: 22 | V10: N | W10: 0 | X10: 22 | Y10: 22 | Z10: N | AA10: 0 | AB10: 22 | AC10: 22 | AD10: N | AE10: 0 | AF10: 22 | AG10: 22 | AH10: N | AI10: 0 | AJ10: 22 | AK10: 22 | AL10: N | AM10: 0 | AN10: 21 | AO10: 20 | AP10: N | AQ10: 0 | AR10: 11 | AS10: 12 | AT10: N | AU10: 1 | AV10: 22 | AW10: 22 | AX10: N | AY10: 0 | AZ10: 22 | BA10: 22 | BB10: N | BC10: 0 | BD10: 22 | BE10: 22 | BF10: N | BG10: 0 | BH10: 11 | BI10: 14 | BJ10: N | BK10: 1 | BL10: 8 | BM10: 8 | BN10: N | BO10: 4 | BP10: 22 | BQ10: 22 | BR10: N | BS10: 0 | BT10: 21 | BU10: 7 | BV10: N | BW10: 0 | BX10: 8 | BY10: 6 | BZ10: N | CA10: 4 | CB10: 0

Sheet S1Schedule
A1: Race
A2: Bahrain
A3: Jeddah
A4: Australia
A5: Miami
A6: Spain
A7: Canada
A8: Austria
A9: Silverstone
A10: Spa
A11: Zandvoort
A12: Monza
... A20: Abu Dhabi

Sheet Season2
A1: Team | B1: Driver | C1: Username | D1: SuzukaPlace | E1: SuzukaQualifying | F1: SuzukaFastestLap | G1: SuzukaPoints | H1: MonacoPlace | I1: MonacoQualifying | J1: MonacoFastestLap | K1: MonacoPoints | L1: Abu DhabiPlace | M1: Abu DhabiQualifying | N1: Abu DhabiFastestLap | O1: Abu DhabiPoints | P1: MonzaPlace | Q1: MonzaQualifying | R1: MonzaFastestLap | S1: MonzaPoints | T1: ZandvoortPlace | U1: ZandvoortQualifying | V1: ZandvoortFastestLap | W1: ZandvoortPoints | X1: SilverstonePlace | Y1: SilverstoneQualifying | Z1: SilverstoneFastestLap | AA1: SilverstonePoints | AB1: ChinaPlace | AC1: ChinaQualifying | AD1: ChinaFastestLap | AE1: ChinaPoints | AF1: COTAPlace | AG1: COTAQualifying | AH1: COTAFastestLap | AI1: COTAPoints | AJ1: SpaPlace | AK1: SpaQualifying | AL1: SpaFastestLap | AM1: SpaPoints | AN1: AustriaPlace | AO1: AustriaQualifying | AP1: AustriaFastestLap | AQ1: AustriaPoints | AR1: Starting
A2: McLaren | B2: Nick | C2: infmsmantis | D2: 1 | E2: 2 | F2: N | G2: 30 | H2: 11 | I2: 1 | J2: N | K2: 6 | L2: 1 | M2: 2 | N2: N | O2: 31 | P2: 1 | Q2: 2 | R2: N | S2: 30 | T2: 1 | U2: 3 | V2: N | W2: 30 | X2: 4 | Y2: 1 | Z2: Y | AA2: 18 | AB2: 1 | AC2: 1 | AD2: Y | AE2: 31 | AF2: 2 | AG2: 2 | AH2: N | AI2: 23 | AJ2: 1 | AK2: 1 | AL2: N | AM2: 30 | AN2: 2 | AO2: 1 | AP2: Y | AQ2: 19 | AR2: 0
A3: McLaren | B3: Gary | C3: Mediummnh | D3: 21 | E3: 19 | F3: N | G3: 0 | H3: 21 | I3: 17 | J3: N | K3: 0 | L3: 10 | M3: 10 | N3: N | O3: 4 | P3: 12 | Q3: 13 | R3: N | S3: 1 | T3: 11 | U3: 19 | V3: N | W3: 1 | X3: 12 | Y3: 10 | Z3: N | AA3: 3 | AB3: 22 | AC3: 22 | AD3: N | AE3: 0 | AF3: 11 | AG3: 20 | AH3: N | AI3: 1 | AJ3: 21 | AK3: 17 | AL3: N | AM3: 0 | AN3: 22 | AO3: 22 | AP3: N | AQ3: 0 | AR3: 0
A4: Mercedes | B4: Del | C4: DELREAL718 | D4: 3 | E4: 1 | F4: Y | G4: 21 | H4: 7 | I4: 3 | J4: Y | K4: 10 | L4: 8 | M4: 3 | N4: N | O4: 6 | P4: 3 | Q4: 3 | R4: N | S4: 20 | T4: 5 | U4: 1 | V4: N | W4: 13 | X4: 1 | Y4: 6 | Z4: N | AA4: 30 | AB4: 2 | AC4: 3 | AD4: N | AE4: 23 | AF4: 3 | AG4: 7 | AH4: N | AI4: 20 | AJ4: 2 | AK4: 7 | AL4: N | AM4: 23 | AN4: 1 | AO4: 5 | AP4: N | AQ4: 25 | AR4: 0
A5: Mercedes | B5: Boz | C5: Bositive | D5: 6 | E5: 5 | F5: N | G5: 9 | H5: 21 | I5: 19 | J5: N | K5: 0 | L5: 13 | M5: 9 | N5: N | O5: 1 | P5: 13 | Q5: 7 | R5: N | S5: 0 | T5: 23 | U5: 20 | V5: N | W5: 0 | X5: 14 | Y5: 9 | Z5: N | AA5: 2 | AB5: 8 | AC5: 4 | AD5: N | AE5: 6 | AF5: 9 | AG5: 6 | AH5: N | AI5: 6 | AJ5: 9 | AK5: 10 | AL5: N | AM5: 4 | AN5: 22 | AO5: 22 | AP5: N | AQ5: 0 | AR5: 0
A6: Ferrari | B6: Erick | C6: penguinator2780 | D6: 4 | E6: 4 | F6: N | G6: 17 | H6: 5 | I6: 4 | J6: N | K6: 12 | L6: 3 | M6: 4 | N6: Y | O6: 22 | P6: 4 | Q6: 4 | R6: N | S6: 17 | T6: 2 | U6: 5 | V6: N | W6: 23 | X6: 3 | Y6: 4 | Z6: N | AA6: 20 | AB6: 11 | AC6: 8 | AD6: N | AE6: 5 | AF6: 1 | AG6: 5 | AH6: N | AI6: 30 | AJ6: 3 | AK6: 3 | AL6: Y | AM6: 21 | AN6: 21 | AO6: 20 | AP6: N | AQ6: 0 | AR6: 0
A7: Ferrari | B7: David | C7: KingDavidLivee | D7: 10 | E7: 8 | F7: N | G7: 3 | H7: 14 | I7: 18 | J7: N | K7: 1 | L7: 6 | M7: 8 | N7: N | O7: 11 | P7: 7 | Q7: 6 | R7: N | S7: 9 | T7: 6 | U7: 12 | V7: N | W7: 13 | X7: 13 | Y7: 8 | Z7: N | AA7: 3 | AB7: 10 | AC7: 11 | AD7: N | AE7: 5 | AF7: 7 | AG7: 4 | AH7: N | AI7: 9 | AJ7: 6 | AK7: 5 | AL7: N | AM7: 13 | AN7: 22 | AO7: 22 | AP7: N | AQ7: 0 | AR7: 0
A8: Alpine | B8: Joshua | C8: JoshuaRosario89 | D8: 2 | E8: 3 | F8: N | G8: 23 | H8: 10 | I8: 2 | J8: N | K8: 6 | L8: 2 | M8: 1 | N8: N | O8: 24 | P8: 2 | Q8: 1 | R8: Y | S8: 24 | T8: 3 | U8: 2 | V8: N | W8: 20 | X8: 2 | Y8: 2 | Z8: N | AA8: 23 | AB8: 4 | AC8: 2 | AD8: N | AE8: 17 | AF8: 4 | AG8: 1 | AH8: Y | AI8: 18 | AJ8: 22 | AK8: 22 | AL8: N | AM8: 0 | AN8: 3 | AO8: 2 | AP8: N | AQ8: 15 | AR8: 0
A9: Alpine | B9: Eddie | C9: penguin2780 | D9: 12 | E9: 18 | F9: N | G9: 1 | H9: 21 | I9: 14 | J9: N | K9: 0 | L9: 22 | M9: 22 | N9: N | O9: 0 | P9: 6 | Q9: 5 | R9: N | S9: 13 | T9: 9 | U9: 18 | V9: N | W9: 6 | X9: 11 | Y9: 7 | Z9: N | AA9: 4 | AB9: 12 | AC9: 5 | AD9: N | AE9: 4 | AF9: 6 | AG9: 9 | AH9: N | AI9: 13 | AJ9: 5 | AK9: 6 | AL9: N | AM9: 15 | AN9: 21 | AO9: 6 | AP9: N | AQ9: 0 | AR9: 0
A10: Red Bull | B10: Zane | C10: Tastik45 | D10: 9 | E10: 6 | F10: N | G10: 6 | H10: 9 | I10: 5 | J10: N | K10: 7 | L10: 5 | M10: 5 | N10: N | O10: 16 | P10: 5 | Q10: 8 | R10: N | S10: 13 | T10: 8 | U10: 7 | V10: N | W10: 7 | X10: 9 | Y10: 3 | Z10: N | AA10: 5 | AB10: 3 | AC10: 6 | AD10: N | AE10: 20 | AF10: 5 | AG10: 3 | AH10: N | AI10: 15 | AJ10: 4 | AK10: 2 | AL10: N | AM10: 16 | AN10: 21 | AO10: 3 | AP10: N | AQ10: 0 | AR10: 0
A11: Red Bull | B11: Marcus | C11: oItsBigM | D11: 14 | E11: 10 | F11: N | G11: 1 | H11: 21 | I11: 16 | J11: N | K11: 0 | L11: 4 | M11: 6 | N11: N | O11: 17 | P11: 22 | Q11: 22 | R11: N | S11: 0 | T11: 4 | U11: 6 | V11: N | W11: 15 | X11: 22 | Y11: 22 | Z11: N | AA11: 0 | AB11: 22 | AC11: 22 | AD11: N | AE11: 0 | AF11: 22 | AG11: 22 | AH11: N | AI11: 0 | AJ11: 22 | AK11: 22 | AL11: N | AM11: 0 | AN11: 22 | AO11: 22 | AP11: N | AQ11: 0 | AR11: 0
A12: Alfa Romeo | B12: Josh L | C12: WannaGetRowdy | D12: 15 | E12: 17 | F12: N | G12: 0 | H12: 21 | I12: 20 | J12: N | K12: 0 | L12: 22 | M12: 22 | N12: N | O12: 0 | P12: 22 | Q12: 22 | R12: N | S12: 0 | T12: 22 | U12: 22 | V12: N | W12: 0 | X12: 22 | Y12: 22 | Z12: N | AA12: 0 | AB12: 22 | AC12: 22 | AD12: N | AE12: 0 | AF12: 22 | AG12: 22 | AH12: N | AI12: 0 | AJ12: 22 | AK12: 22 | AL12: N | AM12: 0 | AN12: 22 | AO12: 22 | AP12: N | AQ12: 0 | AR12: 0
A13: Alfa Romeo | B13: Yeti | C13: aYETl | D13: 22 | E13: 22 | F13: N | G13: 0 | H13: 12 | I13: 8 | J13: N | K13: 4 | L13: 7 | M13: 7 | N13: N | O13: 8 | P13: 8 | Q13: 9 | R13: N | S13: 8 | T13: 7 | U13: 4 | V13: N | W13: 11 | X13: 8 | Y13: 5 | Z13: N | AA13: 6 | AB13: 9 | AC13: 7 | AD13: N | AE13: 5 | AF13: 8 | AG13: 8 | AH13: N | AI13: 6 | AJ13: 8 | AK13: 4 | AL13: N | AM13: 6 | AN13: 4 | AO13: 4 | AP13: N | AQ13: 12 | AR13: 0
A14: AlphaTauri | B14: Travis | C14: ImHuntinWabit | D14: 22 | E14: 22 | F14: N | G14: 0 | H14: 22 | I14: 22 | J14: N | K14: 0 | L14: 22 | M14: 22 | N14: N | O14: 0 | P14: 11 | Q14: 20 | R14: N | S14: 1 | T14: 22 | U14: 22 | V14: N | W14: 0 | X14: 22 | Y14: 22 | Z14: N | AA14: 0 | AB14: 22 | AC14: 22 | AD14: N | AE14: 0 | AF14: 22 | AG14: 22 | AH14: N | AI14: 0 | AJ14: 22 | AK14: 22 | AL14: N | AM14: 0 | AN14: 22 | AO14: 22 | AP14: N | AQ14: 0 | AR14: 0

Sheet S2Schedule
A1: Race
A2: Suzuka
A3: Monaco
A4: Abu Dhabi
A5: Monza
A6: Zandvoort
A7: Silverstone
A8: China
A9: COTA
A10: Spa
A11: Austria

Sheet Season3
A1: Team | B1: Driver | C1: Username | D1: SuzukaPlace | E1: SuzukaQualifying | F1: SuzukaFastestLap | G1: SuzukaPoints | H1: SilverstonePlace | I1: SilverstoneQualifying | J1: SilverstoneFastestLap | K1: SilverstonePoints | L1: AustraliaPlace | M1: AustraliaQualifying | N1: AustraliaFastestLap | O1: AustraliaPoints | P1: SpaPlace | Q1: SpaQualifying | R1: SpaFastestLap | S1: SpaPoints | T1: SpainPlace | U1: SpainQualifying | V1: SpainFastestLap | W1: SpainPoints | X1: China SprintPlace | Y1: China SprintQualifying | Z1: China SprintFastestLap | AA1: China SprintPoints | AB1: ChinaPlace | AC1: ChinaQualifying | AD1: ChinaFastestLap | AE1: ChinaPoints | AF1: BakuPlace | AG1: BakuQualifying | AH1: BakuFastestLap | AI1: BakuPoints | AJ1: CanadaPlace | AK1: CanadaQualifying | AL1: CanadaFastestLap | AM1: CanadaPoints | AN1: MonzaPlace | AO1: MonzaQualifying | AP1: MonzaFastestLap | AQ1: MonzaPoints | AR1: Abu DhabiPlace | AS1: Abu DhabiQualifying | AT1: Abu DhabiFastestLap | AU1: Abu DhabiPoints | AV1: Austria SprintPlace | AW1: Austria SprintQualifying | AX1: Austria SprintFastestLap | AY1: Austria SprintPoints | AZ1: AustriaPlace | BA1: AustriaQualifying | BB1: AustriaFastestLap | BC1: AustriaPoints | BD1: COTA SprintPlace | BE1: COTA SprintQualifying | BF1: COTA SprintFastestLap | BG1: COTA SprintPoints | BH1: COTAPlace | BI1: COTAQualifying | BJ1: COTAFastestLap | BK1: COTAPoints | BL1: Starting
A2: McLaren | B2: Nick | C2: infmsmantis | D2: 2 | E2: 2 | F2: N | G2: 18 | H2: 2 | I2: 1 | J2: N | K2: 18 | L2: 1 | M2: 2 | N2: N | O2: 25 | P2: 1 | Q2: 4 | R2: N | S2: 25 | T2: 2 | U2: 1 | V2: N | W2: 18 | X2: 1 | Y2: 2 | Z2: N | AA2: 8 | AB2: 3 | AC2: 20 | AD2: N | AE2: 15 | AF2: 1 | AG2: 1 | AH2: Y | AI2: 26 | AJ2: 2 | AK2: 3 | AL2: N | AM2: 18 | AN2: 1 | AO2: 2 | AP2: N | AQ2: 25 | AR2: 1 | AS2: 1 | AT2: N | AU2: 25 | AV2: 2 | AW2: 2 | AX2: N | AY2: 7 | AZ2: 2 | BA2: 19 | BB2: N | BC2: 18 | BD2: 1 | BE2: 2 | BF2: N | BG2: 8 | BH2: 6 | BI2: 20 | BJ2: N | BK2: 8 | BL2: 0
A3: McLaren | B3: Travis | C3: PrisonMike | D3: 16 | E3: 10 | F3: N | G3: 1 | H3: 9 | I3: 10 | J3: N | K3: 3 | L3: 12 | M3: 7 | N3: N | O3: 1 | P3: 22 | Q3: 22 | R3: N | S3: 0 | T3: 18 | U3: 8 | V3: N | W3: 1 | X3: 22 | Y3: 22 | Z3: N | AA3: 0 | AB3: 22 | AC3: 22 | AD3: N | AE3: 0 | AF3: 15 | AG3: 6 | AH3: N | AI3: 1 | AJ3: 6 | AK3: 8 | AL3: N | AM3: 8 | AN3: 22 | AO3: 22 | AP3: N | AQ3: 0 | AR3: 6 | AS3: 7 | AT3: N | AU3: 8 | AV3: 14 | AW3: 16 | AX3: N | AY3: 0.5 | AZ3: 6 | BA3: 13 | BB3: N | BC3: 8 | BD3: 7 | BE3: 7 | BF3: N | BG3: 2 | BH3: 7 | BI3: 14 | BJ3: N | BK3: 6 | BL3: 0
A4: VCARB | B4: Patrick | C4: PKnowlez | D4: 11 | E4: 4 | F4: N | G4: 1 | H4: 4 | I4: 8 | J4: N | K4: 12 | L4: 4 | M4: 4 | N4: N | O4: 12 | P4: 5 | Q4: 5 | R4: N | S4: 10 | T4: 6 | U4: 6 | V4: Y | W4: 9 | X4: 18 | Y4: 1 | Z4: N | AA4: 0.5 | AB4: 1 | AC4: 3 | AD4: N | AE4: 25 | AF4: 2 | AG4: 2 | AH4: N | AI4: 18 | AJ4: 5 | AK4: 5 | AL4: N | AM4: 10 | AN4: 22 | AO4: 22 | AP4: N | AQ4: 0 | AR4: 20 | AS4: 2 | AT4: Y | AU4: 2 | AV4: 6 | AW4: 5 | AX4: N | AY4: 3 | AZ4: 21 | BA4: 15 | BB4: N | BC4: 0 | BD4: 6 | BE4: 5 | BF4: N | BG4: 3 | BH4: 4 | BI4: 15 | BJ4: N | BK4: 12 | BL4: 0
A5: VCARB | B5: Brently | C5: Brentuar | D5: 5 | E5: 16 | F5: N | G5: 10 | H5: 8 | I5: 6 | J5: N | K5: 4 | L5: 5 | M5: 8 | N5: N | O5: 10 | P5: 4 | Q5: 9 | R5: N | S5: 12 | T5: 4 | U5: 7 | V5: N | W5: 12 | X5: 3 | Y5: 3 | Z5: N | AA5: 6 | AB5: 7 | AC5: 18 | AD5: N | AE5: 6 | AF5: 11 | AG5: 3 | AH5: N | AI5: 1 | AJ5: 8 | AK5: 7 | AL5: N | AM5: 4 | AN5: 3 | AO5: 3 | AP5: N | AQ5: 15 | AR5: 3 | AS5: 3 | AT5: N | AU5: 15 | AV5: 7 | AW5: 6 | AX5: N | AY5: 2 | AZ5: 4 | BA5: 14 | BB5: N | BC5: 12 | BD5: 8 | BE5: 8 | BF5: N | BG5: 1 | BH5: 20 | BI5: 13 | BJ5: N | BK5: 1 | BL5: 0
A6: Ferrari | B6: Erick | C6: penguinator2780 | D6: 7 | E6: 7 | F6: N | G6: 6 | H6: 3 | I6: 4 | J6: N | K6: 15 | L6: 3 | M6: 5 | N6: N | O6: 15 | P6: 6 | Q6: 8 | R6: N | S6: 8 | T6: 3 | U6: 2 | V6: N | W6: 15 | X6: 2 | Y6: 4 | Z6: N | AA6: 7 | AB6: 2 | AC6: 19 | AD6: N | AE6: 18 | AF6: 22 | AG6: 22 | AH6: N | AI6: 0 | AJ6: 4 | AK6: 6 | AL6: N | AM6: 12 | AN6: 5 | AO6: 5 | AP6: N | AQ6: 10 | AR6: 7 | AS6: 6 | AT6: N | AU6: 6 | AV6: 3 | AW6: 4 | AX6: N | AY6: 6 | AZ6: 16 | BA6: 18 | BB6: N | BC6: 1 | BD6: 5 | BE6: 6 | BF6: N | BG6: 4 | BH6: 2 | BI6: 16 | BJ6: N | BK6: 18 | BL6: 0
A7: Ferrari | B7: Zane | C7: Tastik45 | D7: 4 | E7: 3 | F7: N | G7: 12 | H7: 5 | I7: 3 | J7: N | K7: 10 | L7: 15 | M7: 6 | N7: N | O7: 1 | P7: 22 | Q7: 22 | R7: N | S7: 0 | T7: 22 | U7: 22 | V7: N | W7: 0 | X7: 22 | Y7: 22 | Z7: N | AA7: 0 | AB7: 22 | AC7: 22 | AD7: N | AE7: 0 | AF7: 22 | AG7: 22 | AH7: N | AI7: 0 | AJ7: 22 | AK7: 22 | AL7: N | AM7: 0 | AN7: 22 | AO7: 22 | AP7: N | AQ7: 0 | AU7: 0 | AY7: 0 | BC7: 0 | BG7: 0 | BK7: 0 | BL7: 0
A8: Ferrari | B8: Del | C8: DELREAL718 | G8: 0 | K8: 0 | O8: 0 | S8: 0 | W8: 0 | AA8: 0 | AE8: 0 | AI8: 0 | AM8: 0 | AQ8: 0 | AR8: 5 | AS8: 4 | AT8: N | AU8: 10 | AV8: 1 | AW8: 3 | AX8: N | AY8: 8 | AZ8: 3 | BA8: 20 | BB8: N | BC8: 15 | BD8: 4 | BE8: 4 | BF8: N | BG8: 5 | BH8: 3 | BI8: 17 | BJ8: N | BK8: 15 | BL8: 0
A9: Alpine | B9: Eddie | C9: penguin2780 | D9: 8 | E9: 13 | F9: N | G9: 4 | H9: 7 | I9: 9 | J9: N | K9: 6 | L9: 13 | M9: 15 | N9: N | O9: 1 | P9: 7 | Q9: 6 | R9: N | S9: 6 | T9: 19 | U9: 5 | V9: N | W9: 1 | X9: 4 | Y9: 14 | Z9: N | AA9: 5 | AB9: 5 | AC9: 17 | AD9: N | AE9: 10 | AF9: 18 | AG9: 4 | AH9: N | AI9: 1 | AJ9: 7 | AK9: 4 | AL9: N | AM9: 6 | AN9: 4 | AO9: 4 | AP9: N | AQ9: 12 | AR9: 4 | AS9: 10 | AT9: N | AU9: 12 | AV9: 4 | AW9: 1 | AX9: N | AY9: 5 | AZ9: 21 | BA9: 17 | BB9: N | BC9: 0 | BD9: 3 | BE9: 3 | BF9: N | BG9: 6 | BH9: 5 | BI9: 18 | BJ9: N | BK9: 10 | BL9: 0
A10: Alpine | B10: Joshua | C10: JoshuaRosario89 | D10: 1 | E10: 1 | F10: Y | G10: 26 | H10: 1 | I10: 2 | J10: Y | K10: 26 | L10: 2 | M10: 1 | N10: Y | O10: 19 | P10: 2 | Q10: 3 | R10: Y | S10: 19 | T10: 1 | U10: 3 | V10: N | W10: 25 | X10: 21 | Y10: 6 | Z10: N | AA10: 0 | AB10: 4 | AC10: 2 | AD10: Y | AE10: 13 | AF10: 22 | AG10: 22 | AH10: N | AI10: 0 | AJ10: 3 | AK10: 1 | AL10: Y | AM10: 16 | AN10: 22 | AO10: 22 | AP10: N | AQ10: 0 | AR10: 2 | AS10: 15 | AT10: N | AU10: 18 | AV10: 5 | AW10: 15 | AX10: Y | AY10: 5 | AZ10: 1 | BA10: 16 | BB10: Y | BC10: 26 | BD10: 2 | BE10: 1 | BF10: Y | BG10: 8 | BH10: 1 | BI10: 19 | BJ10: Y | BK10: 26 | BL10: 0
A11: Red Bull | B11: Yeti | C11: aYETI | D11: 14 | E11: 19 | F11: N | G11: 1 | H11: 6 | I11: 5 | J11: N | K11: 8 | L11: 21 | M11: 20 | N11: N | O11: 0 | P11: 18 | Q11: 10 | R11: N | S11: 1 | T11: 5 | U11: 14 | V11: N | W11: 10 | X11: 22 | Y11: 22 | Z11: N | AA11: 0 | AB11: 22 | AC11: 22 | AD11: N | AE11: 0 | AF11: 22 | AG11: 22 | AH11: N | AI11: 0 | AJ11: 22 | AK11: 22 | AL11: N | AM11: 0 | AN11: 22 | AO11: 22 | AP11: N | AQ11: 0 | AR11: 22 | AS11: 22 | AT11: N | AU11: 0 | AV11: 22 | AW11: 22 | AX11: N | AY11: 0 | AZ11: 22 | BA11: 22 | BB11: N | BC11: 0 | BD11: 22 | BE11: 22 | BF11: N | BG11: 0 | BH11: 22 | BI11: 22 | BJ11: N | BK11: 0 | BL11: 0
A12: Red Bull | B12: Boz | C12: Bositive | D12: 17 | E12: 8 | F12: N | G12: 1 | H12: 11 | I12: 7 | J12: N | K12: 1 | L12: 21 | M12: 19 | N12: N | O12: 0 | P12: 15 | Q12: 11 | R12: N | S12: 1 | T12: 22 | U12: 22 | V12: N | W12: 0 | X12: 5 | Y12: 15 | Z12: N | AA12: 4 | AB12: 6 | AC12: 16 | AD12: N | AE12: 8 | AF12: 16 | AG12: 5 | AH12: N | AI12: 1 | AJ12: 18 | AK12: 20 | AL12: N | AM12: 1 | AN12: 22 | AO12: 22 | AP12: N | AQ12: 0 | AR12: 10 | AS12: 5 | AT12: N | AU12: 2 | AV12: 22 | AW12: 22 | AX12: N | AY12: 0 | AZ12: 22 | BA12: 22 | BB12: N | BC12: 0 | BD12: 13 | BE12: 20 | BF12: N | BG12: 0.5 | BH12: 18 | BI12: 12 | BJ12: N | BK12: 1 | BL12: 0
A13: Aston Martin | B13: Gary | C13: Mediummnh | D13: 18 | E13: 20 | F13: N | G13: 1 | H13: 19 | I13: 19 | J13: N | K13: 1 | L13: 22 | M13: 22 | N13: N | O13: 0 | P13: 22 | Q13: 22 | R13: N | S13: 0 | T13: 22 | U13: 22 | V13: N | W13: 0 | X13: 22 | Y13: 22 | Z13: N | AA13: 0 | AB13: 22 | AC13: 22 | AD13: N | AE13: 0 | AF13: 22 | AG13: 22 | AH13: N | AI13: 0 | AJ13: 22 | AK13: 22 | AL13: N | AM13: 0 | AN13: 22 | AO13: 22 | AP13: N | AQ13: 0 | AR13: 22 | AS13: 22 | AT13: N | AU13: 0 | AV13: 22 | AW13: 22 | AX13: N | AY13: 0 | AZ13: 22 | BA13: 22 | BB13: N | BC13: 0 | BD13: 22 | BE13: 22 | BF13: N | BG13: 0 | BH13: 22 | BI13: 22 | BJ13: N | BK13: 0 | BL13: 0
A14: Aston Martin | B14: Zane | C14: Tastik45 | G14: 0 | K14: 0 | O14: 0 | S14: 0 | W14: 0 | AA14: 0 | AE14: 0 | AI14: 0 | AM14: 0 | AQ14: 0 | AR14: 22 | AS14: 22 | AT14: N | AU14: 0 | AV14: 22 | AW14: 22 | AX14: N | AY14: 0 | AZ14: 22 | BA14: 22 | BB14: N | BC14: 0 | BD14: 22 | BE14: 22 | BF14: N | BG14: 0 | BH14: 22 | BI14: 22 | BJ14: N | BK14: 0 | BL14: 0
A15: Aston Martin | B15: Del | C15: DELREAL718 | D15: 3 | E15: 18 | F15: N | G15: 15 | H15: 22 | I15: 22 | J15: N | K15: 0 | L15: 11 | M15: 3 | N15: N | O15: 1 | P15: 3 | Q15: 7 | R15: N | S15: 15 | T15: 8 | U15: 4 | V15: N | W15: 4 | X15: 22 | Y15: 22 | Z15: N | AA15: 0 | AB15: 22 | AC15: 22 | AD15: N | AE15: 0 | AF15: 21 | AG15: 22 | AH15: N | AI15: 0 | AJ15: 1 | AK15: 2 | AL15: N | AM15: 25 | AN15: 2 | AO15: 1 | AP15: Y | AQ15: 19 | AU15: 0 | AY15: 0 | BC15: 0 | BG15: 0 | BK15: 0 | BL15: 0

Sheet S3Schedule
A1: Race | B1: Date
A2: Pre-Season: Miami | B2: 45609
A3: Suzuka | B3: 45616
A4: Silverstone | B4: 45630
A5: Australia | B5: 45637
A6: Spa | B6: 45658
A7: Spain | B7: 45658
A8: China Sprint | B8: 45665
A9: China | B9: 45665
A10: Baku | B10: 45672
A11: Canada | B11: 45679
A12: Monza | B12: 45686
A13: Abu Dhabi | B13: 45693
... A18: Post-Season: Monaco | B18: 45707

Sheet Season4
A1: Team | B1: Driver | C1: Username | D1: BahrainPlace | E1: BahrainQualifying | F1: BahrainFastestLap | G1: BahrainDOTD | H1: BahrainMOT | I1: BahrainCD | J1: BahrainPoints | K1: Miami SprintPlace | L1: Miami SprintQualifying | M1: Miami SprintFastestLap | N1: Miami SprintDOTD | O1: Miami SprintMOT | P1: Miami SprintCD | Q1: Miami SprintPoints | R1: MiamiPlace | S1: MiamiQualifying | T1: MiamiFastestLap | U1: MiamiDOTD | V1: MiamiMOT | W1: MiamiCD | X1: MiamiPoints | Y1: SpainPlace | Z1: SpainQualifying | AA1: SpainFastestLap | AB1: SpainDOTD | AC1: SpainMOT | AD1: SpainCD | AE1: SpainPoints | AF1: MexicoPlace | AG1: MexicoQualifying | AH1: MexicoFastestLap | AI1: MexicoDOTD | AJ1: MexicoMOT | AK1: MexicoCD | AL1: MexicoPoints | AM1: BakuPlace | AN1: BakuQualifying | AO1: BakuFastestLap | AP1: BakuDOTD | AQ1: BakuMOT | AR1: BakuCD | AS1: BakuPoints | AT1: Austria ReversePlace | AU1: Austria ReverseQualifying | AV1: Austria ReverseFastestLap | AW1: Austria ReverseDOTD | AX1: Austria ReverseMOT | AY1: Austria ReverseCD | AZ1: Austria ReversePoints | BA1: Spa SprintPlace | BB1: Spa SprintQualifying | BC1: Spa SprintFastestLap | BD1: Spa SprintDOTD | BE1: Spa SprintMOT | BF1: Spa SprintCD | BG1: Spa SprintPoints | BH1: SpaPlace | BI1: SpaQualifying | BJ1: SpaFastestLap | BK1: SpaDOTD | BL1: SpaMOT | BM1: SpaCD | BN1: SpaPoints | BO1: Brazil SprintPlace | BP1: Brazil SprintQualifying | BQ1: Brazil SprintFastestLap | BR1: Brazil SprintDOTD | BS1: Brazil SprintMOT | BT1: Brazil SprintCD | BU1: Brazil SprintPoints | BV1: BrazilPlace | BW1: BrazilQualifying | BX1: BrazilFastestLap | BY1: BrazilDOTD | BZ1: BrazilMOT | CA1: BrazilCD | CB1: BrazilPoints | CC1: AustriaPlace | CD1: AustriaQualifying | CE1: AustriaFastestLap | CF1: AustriaDOTD | CG1: AustriaMOT | CH1: AustriaCD | CI1: AustriaPoints | CJ1: ZandvoortPlace | CK1: ZandvoortQualifying | CL1: ZandvoortFastestLap | CM1: ZandvoortDOTD | CN1: ZandvoortMOT | CO1: ZandvoortCD | CP1: ZandvoortPoints | CQ1: JeddahPlace | CR1: JeddahQualifying | CS1: JeddahFastestLap | CT1: JeddahDOTD | CU1: JeddahMOT | CV1: JeddahCD | CW1: JeddahPoints | CX1: Las VegasPlace | CY1: Las VegasQualifying | CZ1: Las VegasFastestLap | DA1: Las VegasDOTD | DB1: Las VegasMOT | DC1: Las VegasCD | DD1: Las VegasPoints | DE1: Abu DhabiPlace | DF1: Abu DhabiQualifying | DG1: Abu DhabiFastestLap | DH1: Abu DhabiDOTD | DI1: Abu DhabiMOT | DJ1: Abu DhabiCD | DK1: Abu DhabiPoints | DL1: MonzaPlace | DM1: MonzaQualifying | DN1: MonzaFastestLap | DO1: MonzaDOTD | DP1: MonzaMOT | DQ1: MonzaCD | DR1: MonzaPoints | DS1: Starting
A2: Alpine | B2: Joshua | C2: JoshuaRosario89 | D2: 2 | E2: 3 | F2: y | G2: n | H2: n | I2: n | J2: =IFERROR((VLOOKUP(D2,Scoring!$A:$B,2,0))+IF(F2="y",1,0)+IF(G2="y",1,0)+IF(H2="y",1,0)+IF(I2="y",1,0),0) -> 19 | K2: 8 | L2: 2 | M2: n | N2: n | O2: n | P2: n | Q2: =IFERROR((VLOOKUP(K2,Scoring!$D:$E,2,0))+IF(M2="y",1,0)+IF(N2="y",1,0)+IF(O2="y",1,0)+IF(P2="y",1,0),0) -> 1 | R2: 3 | S2: 7 | T2: n | U2: y | V2: n | W2: n | X2: =IFERROR((VLOOKUP(R2,Scoring!$A:$B,2,0))+IF(T2="y",1,0)+IF(U2="y",1,0)+IF(V2="y",1,0)+IF(W2="y",1,0),0) -> 16 | Y2: 2 | Z2: 2 | AA2: y | AB2: n | AC2: n | AD2: n | AE2: =IFERROR((VLOOKUP(Y2,Scoring!$A:$B,2,0))+IF(AA2="y",1,0)+IF(AB2="y",1,0)+IF(AC2="y",1,0)+IF(AD2="y",1,0),0) -> 19 | AF2: 5 | AG2: 2 | AH2: n | AI2: n | AJ2: n | AK2: n | AL2: =IFERROR((VLOOKUP(AF2,Scoring!$A:$B,2,0))+IF(AH2="y",1,0)+IF(AI2="y",1,0)+IF(AJ2="y",1,0)+IF(AK2="y",1,0),0) -> 10 | AM2: 2 | AN2: 2 | AO2: n | AP2: n | AQ2: n | AR2: n | AS2: =IFERROR((VLOOKUP(AM2,Scoring!$A:$B,2,0))+IF(AO2="y",1,0)+IF(AP2="y",1,0)+IF(AQ2="y",1,0)+IF(AR2="y",1,0),0) -> 18 | AT2: 2 | AU2: 1 | AV2: n | AW2: n | AX2: n | AY2: n | AZ2: =IFERROR((VLOOKUP(AT2,Scoring!$A:$B,2,0))+IF(AV2="y",1,0)+IF(AW2="y",1,0)+IF(AX2="y",1,0)+IF(AY2="y",1,0),0) -> 18 | BA2: 4 | BB2: 1 | BC2: n | BD2: n | BE2: n | BF2: n | BG2: =IFERROR((VLOOKUP(BA2,Scoring!$D:$E,2,0))+IF(BC2="y",1,0)+IF(BD2="y",1,0)+IF(BE2="y",1,0)+IF(BF2="y",1,0),0) -> 5 | BH2: 6 | BI2: 12 | BJ2: y | BK2: n | BL2: n | BM2: n | BN2: =IFERROR((VLOOKUP(BH2,Scoring!$A:$B,2,0))+IF(BJ2="y",1,0)+IF(BK2="y",1,0)+IF(BL2="y",1,0)+IF(BM2="y",1,0),0) -> 9 | BO2: 1 | BP2: 1 | BQ2: n | BR2: n | BS2: n | BT2: n | BU2: =IFERROR((VLOOKUP(BO2,Scoring!$D:$E,2,0))+IF(BQ2="y",1,0)+IF(BR2="y",1,0)+IF(BS2="y",1,0)+IF(BT2="y",1,0),0) -> 8 | BV2: 2 | BW2: 15 | BX2: n | BY2: n | BZ2: y | CA2: n | CB2: =IFERROR((VLOOKUP(BV2,Scoring!$A:$B,2,0))+IF(BX2="y",1,0)+IF(BY2="y",1,0)+IF(BZ2="y",1,0)+IF(CA2="y",1,0),0) -> 19 | CC2: 2 | CD2: 1 | CE2: n | CF2: n | CG2: n | CH2: n | CI2: =IFERROR((VLOOKUP(CC2,Scoring!$A:$B,2,0))+IF(CE2="y",1,0)+IF(CF2="y",1,0)+IF(CG2="y",1,0)+IF(CH2="y",1,0),0) -> 18 | CJ2: 1 | CK2: 1 | CL2: y | CM2: n | CN2: n | CO2: n | CP2: =IFERROR((VLOOKUP(CJ2,Scoring!$A:$B,2,0))+IF(CL2="y",1,0)+IF(CM2="y",1,0)+IF(CN2="y",1,0)+IF(CO2="y",1,0),0) -> 26 | CQ2: 1 | CR2: 2 | CS2: y | CT2: n | CU2: n | CV2: n | CW2: =IFERROR((VLOOKUP(CQ2,Scoring!$A:$B,2,0))+IF(CS2="y",1,0)+IF(CT2="y",1,0)+IF(CU2="y",1,0)+IF(CV2="y",1,0),0) -> 26 | CX2: 5 | CY2: 1 | CZ2: n | DA2: n | DB2: n | DC2: n | DD2: =IFERROR((VLOOKUP(CX2,Scoring!$A:$B,2,0))+IF(CZ2="y",1,0)+IF(DA2="y",1,0)+IF(DB2="y",1,0)+IF(DC2="y",1,0),0) -> 10 | DE2: 3 | DF2: 3 | DG2: n | DH2: n | DI2: n | DJ2: n | DK2: =IFERROR((VLOOKUP(DE2,Scoring!$A:$B,2,0))+IF(DG2="y",1,0)+IF(DH2="y",1,0)+IF(DI2="y",1,0)+IF(DJ2="y",1,0),0) -> 15 | DL2: 2 | DM2: 9 | DN2: n | DO2: y | DP2: n | DQ2: n | DR2: =IFERROR((VLOOKUP(DL2,Scoring!$A:$B,2,0))+IF(DN2="y",1,0)+IF(DO2="y",1,0)+IF(DP2="y",1,0)+IF(DQ2="y",1,0),0) -> 19 | DS2: 0
A3: Alpine | B3: Eddie | C3: penguin2780 | D3: 10 | E3: 6 | F3: n | G3: y | H3: y | I3: n | J3: =IFERROR((VLOOKUP(D3,Scoring!$A:$B,2,0))+IF(F3="y",1,0)+IF(G3="y",1,0)+IF(H3="y",1,0)+IF(I3="y",1,0),0) -> 4 | K3: 22 | L3: 22 | M3: n | N3: n | O3: n | P3: n | Q3: =IFERROR((VLOOKUP(K3,Scoring!$D:$E,2,0))+IF(M3="y",1,0)+IF(N3="y",1,0)+IF(O3="y",1,0)+IF(P3="y",1,0),0) -> 0 | R3: 22 | S3: 22 | T3: n | U3: n | V3: n | W3: n | X3: =IFERROR((VLOOKUP(R3,Scoring!$A:$B,2,0))+IF(T3="y",1,0)+IF(U3="y",1,0)+IF(V3="y",1,0)+IF(W3="y",1,0),0) -> 0 | Y3: 11 | Z3: 7 | AA3: n | AB3: n | AC3: n | AD3: n | AE3: =IFERROR((VLOOKUP(Y3,Scoring!$A:$B,2,0))+IF(AA3="y",1,0)+IF(AB3="y",1,0)+IF(AC3="y",1,0)+IF(AD3="y",1,0),0) -> 1 | AF3: 22 | AG3: 22 | AH3: n | AI3: n | AJ3: n | AK3: n | AL3: =IFERROR((VLOOKUP(AF3,Scoring!$A:$B,2,0))+IF(AH3="y",1,0)+IF(AI3="y",1,0)+IF(AJ3="y",1,0)+IF(AK3="y",1,0),0) -> 0 | AM3: 21 | AN3: 6 | AO3: n | AP3: n | AQ3: n | AR3: n | AS3: =IFERROR((VLOOKUP(AM3,Scoring!$A:$B,2,0))+IF(AO3="y",1,0)+IF(AP3="y",1,0)+IF(AQ3="y",1,0)+IF(AR3="y",1,0),0) -> 0 | AT3: 7 | AU3: 6 | AV3: n | AW3: n | AX3: n | AY3: n | AZ3: =IFERROR((VLOOKUP(AT3,Scoring!$A:$B,2,0))+IF(AV3="y",1,0)+IF(AW3="y",1,0)+IF(AX3="y",1,0)+IF(AY3="y",1,0),0) -> 6 | BA3: 6 | BB3: 8 | BC3: n | BD3: n | BE3: n | BF3: n | BG3: =IFERROR((VLOOKUP(BA3,Scoring!$D:$E,2,0))+IF(BC3="y",1,0)+IF(BD3="y",1,0)+IF(BE3="y",1,0)+IF(BF3="y",1,0),0) -> 3 | BH3: 5 | BI3: 10 | BJ3: n | BK3: n | BL3: n | BM3: n | BN3: =IFERROR((VLOOKUP(BH3,Scoring!$A:$B,2,0))+IF(BJ3="y",1,0)+IF(BK3="y",1,0)+IF(BL3="y",1,0)+IF(BM3="y",1,0),0) -> 10 | BO3: 8 | BP3: 9 | BQ3: n | BR3: n | BS3: n | BT3: n | BU3: =IFERROR((VLOOKUP(BO3,Scoring!$D:$E,2,0))+IF(BQ3="y",1,0)+IF(BR3="y",1,0)+IF(BS3="y",1,0)+IF(BT3="y",1,0),0) -> 1 | BV3: 8 | BW3: 8 | BX3: n | BY3: n | BZ3: n | CA3: n | CB3: =IFERROR((VLOOKUP(BV3,Scoring!$A:$B,2,0))+IF(BX3="y",1,0)+IF(BY3="y",1,0)+IF(BZ3="y",1,0)+IF(CA3="y",1,0),0) -> 4 | CC3: 10 | CD3: 22 | CE3: n | CF3: n | CG3: y | CH3: n | CI3: =IFERROR((VLOOKUP(CC3,Scoring!$A:$B,2,0))+IF(CE3="y",1,0)+IF(CF3="y",1,0)+IF(CG3="y",1,0)+IF(CH3="y",1,0),0) -> 3 | CJ3: 12 | CK3: 6 | CL3: n | CM3: n | CN3: n | CO3: n | CP3: =IFERROR((VLOOKUP(CJ3,Scoring!$A:$B,2,0))+IF(CL3="y",1,0)+IF(CM3="y",1,0)+IF(CN3="y",1,0)+IF(CO3="y",1,0),0) -> 1 | CQ3: 7 | CR3: 14 | CS3: n | CT3: n | CU3: n | CV3: n | CW3: =IFERROR((VLOOKUP(CQ3,Scoring!$A:$B,2,0))+IF(CS3="y",1,0)+IF(CT3="y",1,0)+IF(CU3="y",1,0)+IF(CV3="y",1,0),0) -> 6 | CX3: 22 | CY3: 22 | CZ3: n | DA3: n | DB3: n | DC3: n | DD3: =IFERROR((VLOOKUP(CX3,Scoring!$A:$B,2,0))+IF(CZ3="y",1,0)+IF(DA3="y",1,0)+IF(DB3="y",1,0)+IF(DC3="y",1,0),0) -> 0 | DE3: 5 | DF3: 8 | DG3: n | DH3: n | DI3: n | DJ3: n | DK3: =IFERROR((VLOOKUP(DE3,Scoring!$A:$B,2,0))+IF(DG3="y",1,0)+IF(DH3="y",1,0)+IF(DI3="y",1,0)+IF(DJ3="y",1,0),0) -> 10 | DL3: 11 | DM3: 16 | DN3: n | DO3: n | DP3: n | DQ3: n | DR3: =IFERROR((VLOOKUP(DL3,Scoring!$A:$B,2,0))+IF(DN3="y",1,0)+IF(DO3="y",1,0)+IF(DP3="y",1,0)+IF(DQ3="y",1,0),0) -> 1 | DS3: 0
A4: McLaren | B4: Nick | C4: infmsmantis | D4: 3 | E4: 2 | F4: n | G4: n | H4: n | I4: n | J4: =IFERROR((VLOOKUP(D4,Scoring!$A:$B,2,0))+IF(F4="y",1,0)+IF(G4="y",1,0)+IF(H4="y",1,0)+IF(I4="y",1,0),0) -> 15 | K4: 4 | L4: 3 | M4: n | N4: n | O4: n | P4: n | Q4: =IFERROR((VLOOKUP(K4,Scoring!$D:$E,2,0))+IF(M4="y",1,0)+IF(N4="y",1,0)+IF(O4="y",1,0)+IF(P4="y",1,0),0) -> 5 | R4: 1 | S4: 11 | T4: n | U4: n | V4: y | W4: n | X4: =IFERROR((VLOOKUP(R4,Scoring!$A:$B,2,0))+IF(T4="y",1,0)+IF(U4="y",1,0)+IF(V4="y",1,0)+IF(W4="y",1,0),0) -> 26 | Y4: 10 | Z4: 14 | AA4: n | AB4: n | AC4: y | AD4: y | AE4: =IFERROR((VLOOKUP(Y4,Scoring!$A:$B,2,0))+IF(AA4="y",1,0)+IF(AB4="y",1,0)+IF(AC4="y",1,0)+IF(AD4="y",1,0),0) -> 4 | AF4: 6 | AG4: 4 | AH4: n | AI4: n | AJ4: n | AK4: y | AL4: =IFERROR((VLOOKUP(AF4,Scoring!$A:$B,2,0))+IF(AH4="y",1,0)+IF(AI4="y",1,0)+IF(AJ4="y",1,0)+IF(AK4="y",1,0),0) -> 9 | AM4: 3 | AN4: 5 | AO4: n | AP4: n | AQ4: n | AR4: n | AS4: =IFERROR((VLOOKUP(AM4,Scoring!$A:$B,2,0))+IF(AO4="y",1,0)+IF(AP4="y",1,0)+IF(AQ4="y",1,0)+IF(AR4="y",1,0),0) -> 15 | AT4: 4 | AU4: 2 | AV4: n | AW4: n | AX4: n | AY4: n | AZ4: =IFERROR((VLOOKUP(AT4,Scoring!$A:$B,2,0))+IF(AV4="y",1,0)+IF(AW4="y",1,0)+IF(AX4="y",1,0)+IF(AY4="y",1,0),0) -> 12 | BA4: 7 | BB4: 6 | BC4: n | BD4: n | BE4: n | BF4: n | BG4: =IFERROR((VLOOKUP(BA4,Scoring!$D:$E,2,0))+IF(BC4="y",1,0)+IF(BD4="y",1,0)+IF(BE4="y",1,0)+IF(BF4="y",1,0),0) -> 2 | BH4: 1 | BI4: 9 | BJ4: n | BK4: n | BL4: n | BM4: n | BN4: =IFERROR((VLOOKUP(BH4,Scoring!$A:$B,2,0))+IF(BJ4="y",1,0)+IF(BK4="y",1,0)+IF(BL4="y",1,0)+IF(BM4="y",1,0),0) -> 25 | BO4: 3 | BP4: 4 | BQ4: n | BR4: n | BS4: n | BT4: n | BU4: =IFERROR((VLOOKUP(BO4,Scoring!$D:$E,2,0))+IF(BQ4="y",1,0)+IF(BR4="y",1,0)+IF(BS4="y",1,0)+IF(BT4="y",1,0),0) -> 6 | BV4: 3 | BW4: 12 | BX4: n | BY4: n | BZ4: n | CA4: n | CB4: =IFERROR((VLOOKUP(BV4,Scoring!$A:$B,2,0))+IF(BX4="y",1,0)+IF(BY4="y",1,0)+IF(BZ4="y",1,0)+IF(CA4="y",1,0),0) -> 15 | CC4: 21 | CD4: 3 | CE4: n | CF4: n | CG4: n | CH4: n | CI4: =IFERROR((VLOOKUP(CC4,Scoring!$A:$B,2,0))+IF(CE4="y",1,0)+IF(CF4="y",1,0)+IF(CG4="y",1,0)+IF(CH4="y",1,0),0) -> 0 | CJ4: 4 | CK4: 2 | CL4: n | CM4: n | CN4: n | CO4: n | CP4: =IFERROR((VLOOKUP(CJ4,Scoring!$A:$B,2,0))+IF(CL4="y",1,0)+IF(CM4="y",1,0)+IF(CN4="y",1,0)+IF(CO4="y",1,0),0) -> 12 | CQ4: 4 | CR4: 15 | CS4: n | CT4: y | CU4: y | CV4: n | CW4: =IFERROR((VLOOKUP(CQ4,Scoring!$A:$B,2,0))+IF(CS4="y",1,0)+IF(CT4="y",1,0)+IF(CU4="y",1,0)+IF(CV4="y",1,0),0) -> 14 | CX4: 3 | CY4: 3 | CZ4: n | DA4: n | DB4: n | DC4: n | DD4: =IFERROR((VLOOKUP(CX4,Scoring!$A:$B,2,0))+IF(CZ4="y",1,0)+IF(DA4="y",1,0)+IF(DB4="y",1,0)+IF(DC4="y",1,0),0) -> 15 | DE4: 21 | DF4: 4 | DG4: n | DH4: n | DI4: n | DJ4: n | DK4: =IFERROR((VLOOKUP(DE4,Scoring!$A:$B,2,0))+IF(DG4="y",1,0)+IF(DH4="y",1,0)+IF(DI4="y",1,0)+IF(DJ4="y",1,0),0) -> 0 | DL4: 9 | DM4: 2 | DN4: n | DO4: n | DP4: n | DQ4: n | DR4: =IFERROR((VLOOKUP(DL4,Scoring!$A:$B,2,0))+IF(DN4="y",1,0)+IF(DO4="y",1,0)+IF(DP4="y",1,0)+IF(DQ4="y",1,0),0) -> 3 | DS4: 0
A5: McLaren | B5: Travis | C5: PrisonMike | D5: 22 | E5: 22 | F5: n | G5: n | H5: n | I5: n | J5: =IFERROR((VLOOKUP(D5,Scoring!$A:$B,2,0))+IF(F5="y",1,0)+IF(G5="y",1,0)+IF(H5="y",1,0)+IF(I5="y",1,0),0) -> 0 | K5: 7 | L5: 9 | M5: n | N5: n | O5: n | P5: n | Q5: =IFERROR((VLOOKUP(K5,Scoring!$D:$E,2,0))+IF(M5="y",1,0)+IF(N5="y",1,0)+IF(O5="y",1,0)+IF(P5="y",1,0),0) -> 2 | R5: 5 | S5: 8 | T5: n | U5: n | V5: n | W5: n | X5: =IFERROR((VLOOKUP(R5,Scoring!$A:$B,2,0))+IF(T5="y",1,0)+IF(U5="y",1,0)+IF(V5="y",1,0)+IF(W5="y",1,0),0) -> 10 | Y5: 13 | Z5: 13 | AA5: n | AB5: n | AC5: n | AD5: n | AE5: =IFERROR((VLOOKUP(Y5,Scoring!$A:$B,2,0))+IF(AA5="y",1,0)+IF(AB5="y",1,0)+IF(AC5="y",1,0)+IF(AD5="y",1,0),0) -> 1 | AF5: 10 | AG5: 11 | AH5: n | AI5: n | AJ5: n | AK5: n | AL5: =IFERROR((VLOOKUP(AF5,Scoring!$A:$B,2,0))+IF(AH5="y",1,0)+IF(AI5="y",1,0)+IF(AJ5="y",1,0)+IF(AK5="y",1,0),0) -> 2 | AM5: 21 | AN5: 9 | AO5: n | AP5: n | AQ5: n | AR5: n | AS5: =IFERROR((VLOOKUP(AM5,Scoring!$A:$B,2,0))+IF(AO5="y",1,0)+IF(AP5="y",1,0)+IF(AQ5="y",1,0)+IF(AR5="y",1,0),0) -> 0 | AT5: 22 | AU5: 22 | AV5: n | AW5: n | AX5: n | AY5: n | AZ5: =IFERROR((VLOOKUP(AT5,Scoring!$A:$B,2,0))+IF(AV5="y",1,0)+IF(AW5="y",1,0)+IF(AX5="y",1,0)+IF(AY5="y",1,0),0) -> 0 | BA5: 22 | BB5: 22 | BC5: n | BD5: n | BE5: n | BF5: n | BG5: =IFERROR((VLOOKUP(BA5,Scoring!$D:$E,2,0))+IF(BC5="y",1,0)+IF(BD5="y",1,0)+IF(BE5="y",1,0)+IF(BF5="y",1,0),0) -> 0 | BH5: 22 | BI5: 22 | BJ5: n | BK5: n | BL5: n | BM5: n | BN5: =IFERROR((VLOOKUP(BH5,Scoring!$A:$B,2,0))+IF(BJ5="y",1,0)+IF(BK5="y",1,0)+IF(BL5="y",1,0)+IF(BM5="y",1,0),0) -> 0 | BO5: 22 | BP5: 22 | BQ5: n | BR5: n | BS5: n | BT5: n | BU5: =IFERROR((VLOOKUP(BO5,Scoring!$D:$E,2,0))+IF(BQ5="y",1,0)+IF(BR5="y",1,0)+IF(BS5="y",1,0)+IF(BT5="y",1,0),0) -> 0 | BV5: 22 | BW5: 22 | BX5: n | BY5: n | BZ5: n | CA5: n | CB5: =IFERROR((VLOOKUP(BV5,Scoring!$A:$B,2,0))+IF(BX5="y",1,0)+IF(BY5="y",1,0)+IF(BZ5="y",1,0)+IF(CA5="y",1,0),0) -> 0 | CC5: 22 | CD5: 22 | CE5: n | CF5: n | CG5: n | CH5: n | CI5: =IFERROR((VLOOKUP(CC5,Scoring!$A:$B,2,0))+IF(CE5="y",1,0)+IF(CF5="y",1,0)+IF(CG5="y",1,0)+IF(CH5="y",1,0),0) -> 0 | CJ5: 22 | CK5: 22 | CL5: n | CM5: n | CN5: n | CO5: n | CP5: =IFERROR((VLOOKUP(CJ5,Scoring!$A:$B,2,0))+IF(CL5="y",1,0)+IF(CM5="y",1,0)+IF(CN5="y",1,0)+IF(CO5="y",1,0),0) -> 0 | CQ5: 22 | CR5: 22 | CS5: n | CT5: n | CU5: n | CV5: n | CW5: =IFERROR((VLOOKUP(CQ5,Scoring!$A:$B,2,0))+IF(CS5="y",1,0)+IF(CT5="y",1,0)+IF(CU5="y",1,0)+IF(CV5="y",1,0),0) -> 0 | CX5: 22 | CY5: 22 | CZ5: n | DA5: n | DB5: n | DC5: n | DD5: =IFERROR((VLOOKUP(CX5,Scoring!$A:$B,2,0))+IF(CZ5="y",1,0)+IF(DA5="y",1,0)+IF(DB5="y",1,0)+IF(DC5="y",1,0),0) -> 0 | DE5: 22 | DF5: 22 | DG5: n | DH5: n | DI5: n | DJ5: n | DK5: =IFERROR((VLOOKUP(DE5,Scoring!$A:$B,2,0))+IF(DG5="y",1,0)+IF(DH5="y",1,0)+IF(DI5="y",1,0)+IF(DJ5="y",1,0),0) -> 0 | DL5: 22 | DM5: 22 | DN5: n | DO5: n | DP5: n | DQ5: n | DR5: =IFERROR((VLOOKUP(DL5,Scoring!$A:$B,2,0))+IF(DN5="y",1,0)+IF(DO5="y",1,0)+IF(DP5="y",1,0)+IF(DQ5="y",1,0),0) -> 0 | DS5: 0
A6: VCARB | B6: Patrick | C6: PKnowlez | D6: 1 | E6: 4 | F6: n | G6: n | H6: n | I6: n | J6: =IFERROR((VLOOKUP(D6,Scoring!$A:$B,2,0))+IF(F6="y",1,0)+IF(G6="y",1,0)+IF(H6="y",1,0)+IF(I6="y",1,0),0) -> 25 | K6: 3 | L6: 5 | M6: n | N6: n | O6: n | P6: n | Q6: =IFERROR((VLOOKUP(K6,Scoring!$D:$E,2,0))+IF(M6="y",1,0)+IF(N6="y",1,0)+IF(O6="y",1,0)+IF(P6="y",1,0),0) -> 6 | R6: 9 | S6: 12 | T6: y | U6: n | V6: n | W6: y | X6: =IFERROR((VLOOKUP(R6,Scoring!$A:$B,2,0))+IF(T6="y",1,0)+IF(U6="y",1,0)+IF(V6="y",1,0)+IF(W6="y",1,0),0) -> 5 | Y6: 3 | Z6: 6 | AA6: n | AB6: n | AC6: n | AD6: n | AE6: =IFERROR((VLOOKUP(Y6,Scoring!$A:$B,2,0))+IF(AA6="y",1,0)+IF(AB6="y",1,0)+IF(AC6="y",1,0)+IF(AD6="y",1,0),0) -> 15 | AF6: 4 | AG6: 6 | AH6: n | AI6: n | AJ6: n | AK6: n | AL6: =IFERROR((VLOOKUP(AF6,Scoring!$A:$B,2,0))+IF(AH6="y",1,0)+IF(AI6="y",1,0)+IF(AJ6="y",1,0)+IF(AK6="y",1,0),0) -> 12 | AM6: 21 | AN6: 4 | AO6: n | AP6: n | AQ6: n | AR6: n | AS6: =IFERROR((VLOOKUP(AM6,Scoring!$A:$B,2,0))+IF(AO6="y",1,0)+IF(AP6="y",1,0)+IF(AQ6="y",1,0)+IF(AR6="y",1,0),0) -> 0 | AT6: 3 | AU6: 7 | AV6: n | AW6: y | AX6: y | AY6: y | AZ6: =IFERROR((VLOOKUP(AT6,Scoring!$A:$B,2,0))+IF(AV6="y",1,0)+IF(AW6="y",1,0)+IF(AX6="y",1,0)+IF(AY6="y",1,0),0) -> 18 | BA6: 3 | BB6: 4 | BC6: n | BD6: n | BE6: n | BF6: n | BG6: =IFERROR((VLOOKUP(BA6,Scoring!$D:$E,2,0))+IF(BC6="y",1,0)+IF(BD6="y",1,0)+IF(BE6="y",1,0)+IF(BF6="y",1,0),0) -> 6 | BH6: 3 | BI6: 13 | BJ6: n | BK6: n | BL6: n | BM6: y | BN6: =IFERROR((VLOOKUP(BH6,Scoring!$A:$B,2,0))+IF(BJ6="y",1,0)+IF(BK6="y",1,0)+IF(BL6="y",1,0)+IF(BM6="y",1,0),0) -> 16 | BO6: 4 | BP6: 5 | BQ6: n | BR6: n | BS6: n | BT6: n | BU6: =IFERROR((VLOOKUP(BO6,Scoring!$D:$E,2,0))+IF(BQ6="y",1,0)+IF(BR6="y",1,0)+IF(BS6="y",1,0)+IF(BT6="y",1,0),0) -> 5 | BV6: 4 | BW6: 11 | BX6: n | BY6: n | BZ6: n | CA6: n | CB6: =IFERROR((VLOOKUP(BV6,Scoring!$A:$B,2,0))+IF(BX6="y",1,0)+IF(BY6="y",1,0)+IF(BZ6="y",1,0)+IF(CA6="y",1,0),0) -> 12 | CC6: 1 | CD6: 6 | CE6: n | CF6: n | CG6: n | CH6: y | CI6: =IFERROR((VLOOKUP(CC6,Scoring!$A:$B,2,0))+IF(CE6="y",1,0)+IF(CF6="y",1,0)+IF(CG6="y",1,0)+IF(CH6="y",1,0),0) -> 26 | CJ6: 2 | CK6: 3 | CL6: n | CM6: n | CN6: n | CO6: n | CP6: =IFERROR((VLOOKUP(CJ6,Scoring!$A:$B,2,0))+IF(CL6="y",1,0)+IF(CM6="y",1,0)+IF(CN6="y",1,0)+IF(CO6="y",1,0),0) -> 18 | CQ6: 2 | CR6: 5 | CS6: n | CT6: n | CU6: n | CV6: y | CW6: =IFERROR((VLOOKUP(CQ6,Scoring!$A:$B,2,0))+IF(CS6="y",1,0)+IF(CT6="y",1,0)+IF(CU6="y",1,0)+IF(CV6="y",1,0),0) -> 19 | CX6: 2 | CY6: 4 | CZ6: n | DA6: y | DB6: n | DC6: y | DD6: =IFERROR((VLOOKUP(CX6,Scoring!$A:$B,2,0))+IF(CZ6="y",1,0)+IF(DA6="y",1,0)+IF(DB6="y",1,0)+IF(DC6="y",1,0),0) -> 20 | DE6: 21 | DF6: 7 | DG6: n | DH6: n | DI6: n | DJ6: n | DK6: =IFERROR((VLOOKUP(DE6,Scoring!$A:$B,2,0))+IF(DG6="y",1,0)+IF(DH6="y",1,0)+IF(DI6="y",1,0)+IF(DJ6="y",1,0),0) -> 0 | DL6: 4 | DM6: 5 | DN6: n | DO6: n | DP6: n | DQ6: n | DR6: =IFERROR((VLOOKUP(DL6,Scoring!$A:$B,2,0))+IF(DN6="y",1,0)+IF(DO6="y",1,0)+IF(DP6="y",1,0)+IF(DQ6="y",1,0),0) -> 12 | DS6: 0
A7: VCARB | B7: Jelly | C7: JellyWaffles37 | D7: 9 | E7: 7 | F7: n | G7: n | H7: n | I7: n | J7: =IFERROR((VLOOKUP(D7,Scoring!$A:$B,2,0))+IF(F7="y",1,0)+IF(G7="y",1,0)+IF(H7="y",1,0)+IF(I7="y",1,0),0) -> 3 | K7: 6 | L7: 7 | M7: n | N7: n | O7: n | P7: n | Q7: =IFERROR((VLOOKUP(K7,Scoring!$D:$E,2,0))+IF(M7="y",1,0)+IF(N7="y",1,0)+IF(O7="y",1,0)+IF(P7="y",1,0),0) -> 3 | R7: 21 | S7: 9 | T7: n | U7: n | V7: n | W7: n | X7: =IFERROR((VLOOKUP(R7,Scoring!$A:$B,2,0))+IF(T7="y",1,0)+IF(U7="y",1,0)+IF(V7="y",1,0)+IF(W7="y",1,0),0) -> 0 | Y7: 5 | Z7: 3 | AA7: n | AB7: n | AC7: n | AD7: n | AE7: =IFERROR((VLOOKUP(Y7,Scoring!$A:$B,2,0))+IF(AA7="y",1,0)+IF(AB7="y",1,0)+IF(AC7="y",1,0)+IF(AD7="y",1,0),0) -> 10 | AF7: 3 | AG7: 3 | AH7: n | AI7: n | AJ7: n | AK7: n | AL7: =IFERROR((VLOOKUP(AF7,Scoring!$A:$B,2,0))+IF(AH7="y",1,0)+IF(AI7="y",1,0)+IF(AJ7="y",1,0)+IF(AK7="y",1,0),0) -> 15 | AM7: 5 | AN7: 15 | AO7: n | AP7: y | AQ7: y | AR7: n | AS7: =IFERROR((VLOOKUP(AM7,Scoring!$A:$B,2,0))+IF(AO7="y",1,0)+IF(AP7="y",1,0)+IF(AQ7="y",1,0)+IF(AR7="y",1,0),0) -> 12 | AT7: 21 | AU7: 5 | AV7: n | AW7: n | AX7: n | AY7: n | AZ7: =IFERROR((VLOOKUP(AT7,Scoring!$A:$B,2,0))+IF(AV7="y",1,0)+IF(AW7="y",1,0)+IF(AX7="y",1,0)+IF(AY7="y",1,0),0) -> 0 | BA7: 5 | BB7: 5 | BC7: n | BD7: n | BE7: n | BF7: n | BG7: =IFERROR((VLOOKUP(BA7,Scoring!$D:$E,2,0))+IF(BC7="y",1,0)+IF(BD7="y",1,0)+IF(BE7="y",1,0)+IF(BF7="y",1,0),0) -> 4 | BH7: 2 | BI7: 11 | BJ7: n | BK7: n | BL7: y | BM7: n | BN7: =IFERROR((VLOOKUP(BH7,Scoring!$A:$B,2,0))+IF(BJ7="y",1,0)+IF(BK7="y",1,0)+IF(BL7="y",1,0)+IF(BM7="y",1,0),0) -> 19 | BO7: 5 | BP7: 6 | BQ7: n | BR7: n | BS7: n | BT7: n | BU7: =IFERROR((VLOOKUP(BO7,Scoring!$D:$E,2,0))+IF(BQ7="y",1,0)+IF(BR7="y",1,0)+IF(BS7="y",1,0)+IF(BT7="y",1,0),0) -> 4 | BV7: 6 | BW7: 10 | BX7: n | BY7: n | BZ7: n | CA7: n | CB7: =IFERROR((VLOOKUP(BV7,Scoring!$A:$B,2,0))+IF(BX7="y",1,0)+IF(BY7="y",1,0)+IF(BZ7="y",1,0)+IF(CA7="y",1,0),0) -> 8 | CC7: 8 | CD7: 4 | CE7: n | CF7: n | CG7: n | CH7: n | CI7: =IFERROR((VLOOKUP(CC7,Scoring!$A:$B,2,0))+IF(CE7="y",1,0)+IF(CF7="y",1,0)+IF(CG7="y",1,0)+IF(CH7="y",1,0),0) -> 4 | CJ7: 5 | CK7: 8 | CL7: n | CM7: n | CN7: n | CO7: n | CP7: =IFERROR((VLOOKUP(CJ7,Scoring!$A:$B,2,0))+IF(CL7="y",1,0)+IF(CM7="y",1,0)+IF(CN7="y",1,0)+IF(CO7="y",1,0),0) -> 10 | CQ7: 3 | CR7: 6 | CS7: n | CT7: n | CU7: n | CV7: n | CW7: =IFERROR((VLOOKUP(CQ7,Scoring!$A:$B,2,0))+IF(CS7="y",1,0)+IF(CT7="y",1,0)+IF(CU7="y",1,0)+IF(CV7="y",1,0),0) -> 15 | CX7: 21 | CY7: 5 | CZ7: n | DA7: n | DB7: n | DC7: n | DD7: =IFERROR((VLOOKUP(CX7,Scoring!$A:$B,2,0))+IF(CZ7="y",1,0)+IF(DA7="y",1,0)+IF(DB7="y",1,0)+IF(DC7="y",1,0),0) -> 0 | DE7: 2 | DF7: 2 | DG7: n | DH7: n | DI7: n | DJ7: y | DK7: =IFERROR((VLOOKUP(DE7,Scoring!$A:$B,2,0))+IF(DG7="y",1,0)+IF(DH7="y",1,0)+IF(DI7="y",1,0)+IF(DJ7="y",1,0),0) -> 19 | DL7: 3 | DM7: 3 | DN7: n | DO7: n | DP7: n | DQ7: n | DR7: =IFERROR((VLOOKUP(DL7,Scoring!$A:$B,2,0))+IF(DN7="y",1,0)+IF(DO7="y",1,0)+IF(DP7="y",1,0)+IF(DQ7="y",1,0),0) -> 15 | DS7: 0
A8: Red Bull | B8: Brently | C8: Brentuar | D8: 4 | E8: 10 | F8: n | G8: n | H8: n | I8: y | J8: =IFERROR((VLOOKUP(D8,Scoring!$A:$B,2,0))+IF(F8="y",1,0)+IF(G8="y",1,0)+IF(H8="y",1,0)+IF(I8="y",1,0),0) -> 13 | K8: 13 | L8: 6 | M8: n | N8: n | O8: n | P8: n | Q8: =IFERROR((VLOOKUP(K8,Scoring!$D:$E,2,0))+IF(M8="y",1,0)+IF(N8="y",1,0)+IF(O8="y",1,0)+IF(P8="y",1,0),0) -> 0.5 | R8: 2 | S8: 3 | T8: n | U8: n | V8: n | W8: n | X8: =IFERROR((VLOOKUP(R8,Scoring!$A:$B,2,0))+IF(T8="y",1,0)+IF(U8="y",1,0)+IF(V8="y",1,0)+IF(W8="y",1,0),0) -> 18 | Y8: 6 | Z8: 8 | AA8: n | AB8: n | AC8: n | AD8: n | AE8: =IFERROR((VLOOKUP(Y8,Scoring!$A:$B,2,0))+IF(AA8="y",1,0)+IF(AB8="y",1,0)+IF(AC8="y",1,0)+IF(AD8="y",1,0),0) -> 8 | AF8: 8 | AG8: 10 | AH8: n | AI8: n | AJ8: y | AK8: n | AL8: =IFERROR((VLOOKUP(AF8,Scoring!$A:$B,2,0))+IF(AH8="y",1,0)+IF(AI8="y",1,0)+IF(AJ8="y",1,0)+IF(AK8="y",1,0),0) -> 5 | AM8: 9 | AN8: 13 | AO8: n | AP8: n | AQ8: n | AR8: n | AS8: =IFERROR((VLOOKUP(AM8,Scoring!$A:$B,2,0))+IF(AO8="y",1,0)+IF(AP8="y",1,0)+IF(AQ8="y",1,0)+IF(AR8="y",1,0),0) -> 3 | AT8: 12 | AU8: 10 | AV8: n | AW8: n | AX8: n | AY8: n | AZ8: =IFERROR((VLOOKUP(AT8,Scoring!$A:$B,2,0))+IF(AV8="y",1,0)+IF(AW8="y",1,0)+IF(AX8="y",1,0)+IF(AY8="y",1,0),0) -> 1 | BA8: 13 | BB8: 9 | BC8: n | BD8: n | BE8: n | BF8: n | BG8: =IFERROR((VLOOKUP(BA8,Scoring!$D:$E,2,0))+IF(BC8="y",1,0)+IF(BD8="y",1,0)+IF(BE8="y",1,0)+IF(BF8="y",1,0),0) -> 0.5 | BH8: 21 | BI8: 6 | BJ8: n | BK8: n | BL8: n | BM8: n | BN8: =IFERROR((VLOOKUP(BH8,Scoring!$A:$B,2,0))+IF(BJ8="y",1,0)+IF(BK8="y",1,0)+IF(BL8="y",1,0)+IF(BM8="y",1,0),0) -> 0 | BO8: 9 | BP8: 8 | BQ8: n | BR8: n | BS8: n | BT8: n | BU8: =IFERROR((VLOOKUP(BO8,Scoring!$D:$E,2,0))+IF(BQ8="y",1,0)+IF(BR8="y",1,0)+IF(BS8="y",1,0)+IF(BT8="y",1,0),0) -> 0.5 | BV8: 9 | BW8: 7 | BX8: n | BY8: n | BZ8: n | CA8: n | CB8: =IFERROR((VLOOKUP(BV8,Scoring!$A:$B,2,0))+IF(BX8="y",1,0)+IF(BY8="y",1,0)+IF(BZ8="y",1,0)+IF(CA8="y",1,0),0) -> 3 | CC8: 11 | CD8: 7 | CE8: n | CF8: n | CG8: n | CH8: n | CI8: =IFERROR((VLOOKUP(CC8,Scoring!$A:$B,2,0))+IF(CE8="y",1,0)+IF(CF8="y",1,0)+IF(CG8="y",1,0)+IF(CH8="y",1,0),0) -> 1 | CJ8: 10 | CK8: 9 | CL8: n | CM8: n | CN8: y | CO8: n | CP8: =IFERROR((VLOOKUP(CJ8,Scoring!$A:$B,2,0))+IF(CL8="y",1,0)+IF(CM8="y",1,0)+IF(CN8="y",1,0)+IF(CO8="y",1,0),0) -> 3 | CQ8: 22 | CR8: 22 | CS8: n | CT8: n | CU8: n | CV8: n | CW8: =IFERROR((VLOOKUP(CQ8,Scoring!$A:$B,2,0))+IF(CS8="y",1,0)+IF(CT8="y",1,0)+IF(CU8="y",1,0)+IF(CV8="y",1,0),0) -> 0 | CX8: 22 | CY8: 22 | CZ8: n | DA8: n | DB8: n | DC8: n | DD8: =IFERROR((VLOOKUP(CX8,Scoring!$A:$B,2,0))+IF(CZ8="y",1,0)+IF(DA8="y",1,0)+IF(DB8="y",1,0)+IF(DC8="y",1,0),0) -> 0 | DE8: 21 | DF8: 9 | DG8: n | DH8: n | DI8: n | DJ8: n | DK8: =IFERROR((VLOOKUP(DE8,Scoring!$A:$B,2,0))+IF(DG8="y",1,0)+IF(DH8="y",1,0)+IF(DI8="y",1,0)+IF(DJ8="y",1,0),0) -> 0 | DL8: 12 | DM8: 10 | DN8: n | DO8: n | DP8: n | DQ8: n | DR8: =IFERROR((VLOOKUP(DL8,Scoring!$A:$B,2,0))+IF(DN8="y",1,0)+IF(DO8="y",1,0)+IF(DP8="y",1,0)+IF(DQ8="y",1,0),0) -> 1 | DS8: 0
A9: Red Bull | B9: Matthew | C9: NC_Newman | D9: 15 | E9: 5 | F9: n | G9: n | H9: n | I9: n | J9: =IFERROR((VLOOKUP(D9,Scoring!$A:$B,2,0))+IF(F9="y",1,0)+IF(G9="y",1,0)+IF(H9="y",1,0)+IF(I9="y",1,0),0) -> 1 | K9: 9 | L9: 8 | M9: n | N9: n | O9: n | P9: n | Q9: =IFERROR((VLOOKUP(K9,Scoring!$D:$E,2,0))+IF(M9="y",1,0)+IF(N9="y",1,0)+IF(O9="y",1,0)+IF(P9="y",1,0),0) -> 0.5 | R9: 21 | S9: 6 | T9: n | U9: n | V9: n | W9: n | X9: =IFERROR((VLOOKUP(R9,Scoring!$A:$B,2,0))+IF(T9="y",1,0)+IF(U9="y",1,0)+IF(V9="y",1,0)+IF(W9="y",1,0),0) -> 0 | Y9: 4 | Z9: 4 | AA9: n | AB9: n | AC9: n | AD9: n | AE9: =IFERROR((VLOOKUP(Y9,Scoring!$A:$B,2,0))+IF(AA9="y",1,0)+IF(AB9="y",1,0)+IF(AC9="y",1,0)+IF(AD9="y",1,0),0) -> 12 | AF9: 9 | AG9: 8 | AH9: n | AI9: n | AJ9: n | AK9: n | AL9: =IFERROR((VLOOKUP(AF9,Scoring!$A:$B,2,0))+IF(AH9="y",1,0)+IF(AI9="y",1,0)+IF(AJ9="y",1,0)+IF(AK9="y",1,0),0) -> 3 | AM9: 8 | AN9: 11 | AO9: n | AP9: n | AQ9: n | AR9: n | AS9: =IFERROR((VLOOKUP(AM9,Scoring!$A:$B,2,0))+IF(AO9="y",1,0)+IF(AP9="y",1,0)+IF(AQ9="y",1,0)+IF(AR9="y",1,0),0) -> 4 | AT9: 15 | AU9: 9 | AV9: n | AW9: n | AX9: n | AY9: n | AZ9: =IFERROR((VLOOKUP(AT9,Scoring!$A:$B,2,0))+IF(AV9="y",1,0)+IF(AW9="y",1,0)+IF(AX9="y",1,0)+IF(AY9="y",1,0),0) -> 1 | BA9: 9 | BB9: 7 | BC9: n | BD9: n | BE9: n | BF9: n | BG9: =IFERROR((VLOOKUP(BA9,Scoring!$D:$E,2,0))+IF(BC9="y",1,0)+IF(BD9="y",1,0)+IF(BE9="y",1,0)+IF(BF9="y",1,0),0) -> 0.5 | BH9: 8 | BI9: 7 | BJ9: n | BK9: n | BL9: n | BM9: n | BN9: =IFERROR((VLOOKUP(BH9,Scoring!$A:$B,2,0))+IF(BJ9="y",1,0)+IF(BK9="y",1,0)+IF(BL9="y",1,0)+IF(BM9="y",1,0),0) -> 4 | BO9: 14 | BP9: 7 | BQ9: n | BR9: n | BS9: n | BT9: n | BU9: =IFERROR((VLOOKUP(BO9,Scoring!$D:$E,2,0))+IF(BQ9="y",1,0)+IF(BR9="y",1,0)+IF(BS9="y",1,0)+IF(BT9="y",1,0),0) -> 0.5 | BV9: 10 | BW9: 6 | BX9: n | BY9: n | BZ9: n | CA9: n | CB9: =IFERROR((VLOOKUP(BV9,Scoring!$A:$B,2,0))+IF(BX9="y",1,0)+IF(BY9="y",1,0)+IF(BZ9="y",1,0)+IF(CA9="y",1,0),0) -> 2 | CC9: 5 | CD9: 14 | CE9: n | CF9: n | CG9: n | CH9: n | CI9: =IFERROR((VLOOKUP(CC9,Scoring!$A:$B,2,0))+IF(CE9="y",1,0)+IF(CF9="y",1,0)+IF(CG9="y",1,0)+IF(CH9="y",1,0),0) -> 10 | CJ9: 6 | CK9: 11 | CL9: n | CM9: n | CN9: n | CO9: n | CP9: =IFERROR((VLOOKUP(CJ9,Scoring!$A:$B,2,0))+IF(CL9="y",1,0)+IF(CM9="y",1,0)+IF(CN9="y",1,0)+IF(CO9="y",1,0),0) -> 8 | CQ9: 11 | CR9: 4 | CS9: n | CT9: n | CU9: n | CV9: n | CW9: =IFERROR((VLOOKUP(CQ9,Scoring!$A:$B,2,0))+IF(CS9="y",1,0)+IF(CT9="y",1,0)+IF(CU9="y",1,0)+IF(CV9="y",1,0),0) -> 1 | CX9: 21 | CY9: 8 | CZ9: n | DA9: n | DB9: n | DC9: n | DD9: =IFERROR((VLOOKUP(CX9,Scoring!$A:$B,2,0))+IF(CZ9="y",1,0)+IF(DA9="y",1,0)+IF(DB9="y",1,0)+IF(DC9="y",1,0),0) -> 0 | DE9: 6 | DF9: 10 | DG9: n | DH9: n | DI9: n | DJ9: n | DK9: =IFERROR((VLOOKUP(DE9,Scoring!$A:$B,2,0))+IF(DG9="y",1,0)+IF(DH9="y",1,0)+IF(DI9="y",1,0)+IF(DJ9="y",1,0),0) -> 8 | DL9: 8 | DM9: 8 | DN9: n | DO9: n | DP9: y | DQ9: n | DR9: =IFERROR((VLOOKUP(DL9,Scoring!$A:$B,2,0))+IF(DN9="y",1,0)+IF(DO9="y",1,0)+IF(DP9="y",1,0)+IF(DQ9="y",1,0),0) -> 5 | DS9: 0
A10: Aston Martin | B10: Del | C10: DELREAL718 | D10: 5 | E10: 8 | F10: n | G10: n | H10: n | I10: n | J10: =IFERROR((VLOOKUP(D10,Scoring!$A:$B,2,0))+IF(F10="y",1,0)+IF(G10="y",1,0)+IF(H10="y",1,0)+IF(I10="y",1,0),0) -> 10 | K10: 5 | L10: 11 | M10: n | N10: n | O10: n | P10: n | Q10: =IFERROR((VLOOKUP(K10,Scoring!$D:$E,2,0))+IF(M10="y",1,0)+IF(N10="y",1,0)+IF(O10="y",1,0)+IF(P10="y",1,0),0) -> 4 | R10: 6 | S10: 10 | T10: n | U10: n | V10: n | W10: n | X10: =IFERROR((VLOOKUP(R10,Scoring!$A:$B,2,0))+IF(T10="y",1,0)+IF(U10="y",1,0)+IF(V10="y",1,0)+IF(W10="y",1,0),0) -> 8 | Y10: 8 | Z10: 15 | AA10: n | AB10: y | AC10: n | AD10: n | AE10: =IFERROR((VLOOKUP(Y10,Scoring!$A:$B,2,0))+IF(AA10="y",1,0)+IF(AB10="y",1,0)+IF(AC10="y",1,0)+IF(AD10="y",1,0),0) -> 5 | AF10: 7 | AG10: 7 | AH10: n | AI10: n | AJ10: n | AK10: n | AL10: =IFERROR((VLOOKUP(AF10,Scoring!$A:$B,2,0))+IF(AH10="y",1,0)+IF(AI10="y",1,0)+IF(AJ10="y",1,0)+IF(AK10="y",1,0),0) -> 6 | AM10: 7 | AN10: 7 | AO10: n | AP10: n | AQ10: n | AR10: n | AS10: =IFERROR((VLOOKUP(AM10,Scoring!$A:$B,2,0))+IF(AO10="y",1,0)+IF(AP10="y",1,0)+IF(AQ10="y",1,0)+IF(AR10="y",1,0),0) -> 6 | AT10: 6 | AU10: 15 | AV10: n | AW10: n | AX10: n | AY10: n | AZ10: =IFERROR((VLOOKUP(AT10,Scoring!$A:$B,2,0))+IF(AV10="y",1,0)+IF(AW10="y",1,0)+IF(AX10="y",1,0)+IF(AY10="y",1,0),0) -> 8 | BA10: 22 | BB10: 22 | BC10: n | BD10: n | BE10: n | BF10: n | BG10: =IFERROR((VLOOKUP(BA10,Scoring!$D:$E,2,0))+IF(BC10="y",1,0)+IF(BD10="y",1,0)+IF(BE10="y",1,0)+IF(BF10="y",1,0),0) -> 0 | BH10: 22 | BI10: 22 | BJ10: n | BK10: n | BL10: n | BM10: n | BN10: =IFERROR((VLOOKUP(BH10,Scoring!$A:$B,2,0))+IF(BJ10="y",1,0)+IF(BK10="y",1,0)+IF(BL10="y",1,0)+IF(BM10="y",1,0),0) -> 0 | BO10: 22 | BP10: 22 | BQ10: n | BR10: n | BS10: n | BT10: n | BU10: =IFERROR((VLOOKUP(BO10,Scoring!$D:$E,2,0))+IF(BQ10="y",1,0)+IF(BR10="y",1,0)+IF(BS10="y",1,0)+IF(BT10="y",1,0),0) -> 0 | BV10: 22 | BW10: 22 | BX10: n | BY10: n | BZ10: n | CA10: n | CB10: =IFERROR((VLOOKUP(BV10,Scoring!$A:$B,2,0))+IF(BX10="y",1,0)+IF(BY10="y",1,0)+IF(BZ10="y",1,0)+IF(CA10="y",1,0),0) -> 0 | CC10: 4 | CD10: 5 | CE10: n | CF10: n | CG10: n | CH10: n | CI10: =IFERROR((VLOOKUP(CC10,Scoring!$A:$B,2,0))+IF(CE10="y",1,0)+IF(CF10="y",1,0)+IF(CG10="y",1,0)+IF(CH10="y",1,0),0) -> 12 | CJ10: 7 | CK10: 7 | CL10: n | CM10: n | CN10: n | CO10: n | CP10: =IFERROR((VLOOKUP(CJ10,Scoring!$A:$B,2,0))+IF(CL10="y",1,0)+IF(CM10="y",1,0)+IF(CN10="y",1,0)+IF(CO10="y",1,0),0) -> 6 | CQ10: 21 | CR10: 3 | CS10: n | CT10: n | CU10: n | CV10: n | CW10: =IFERROR((VLOOKUP(CQ10,Scoring!$A:$B,2,0))+IF(CS10="y",1,0)+IF(CT10="y",1,0)+IF(CU10="y",1,0)+IF(CV10="y",1,0),0) -> 0 | CX10: 7 | CY10: 7 | CZ10: n | DA10: n | DB10: n | DC10: n | DD10: =IFERROR((VLOOKUP(CX10,Scoring!$A:$B,2,0))+IF(CZ10="y",1,0)+IF(DA10="y",1,0)+IF(DB10="y",1,0)+IF(DC10="y",1,0),0) -> 6 | DE10: 8 | DF10: 11 | DG10: n | DH10: n | DI10: y | DJ10: n | DK10: =IFERROR((VLOOKUP(DE10,Scoring!$A:$B,2,0))+IF(DG10="y",1,0)+IF(DH10="y",1,0)+IF(DI10="y",1,0)+IF(DJ10="y",1,0),0) -> 5 | DL10: 5 | DM10: 6 | DN10: n | DO10: n | DP10: n | DQ10: n | DR10: =IFERROR((VLOOKUP(DL10,Scoring!$A:$B,2,0))+IF(DN10="y",1,0)+IF(DO10="y",1,0)+IF(DP10="y",1,0)+IF(DQ10="y",1,0),0) -> 10 | DS10: 0
A11: Aston Martin | B11: Boz | C11: Bositive | D11: 7 | E11: 12 | F11: n | G11: n | H11: n | I11: n | J11: =IFERROR((VLOOKUP(D11,Scoring!$A:$B,2,0))+IF(F11="y",1,0)+IF(G11="y",1,0)+IF(H11="y",1,0)+IF(I11="y",1,0),0) -> 6 | K11: 21 | L11: 10 | M11: n | N11: n | O11: n | P11: n | Q11: =IFERROR((VLOOKUP(K11,Scoring!$D:$E,2,0))+IF(M11="y",1,0)+IF(N11="y",1,0)+IF(O11="y",1,0)+IF(P11="y",1,0),0) -> 0 | R11: 11 | S11: 15 | T11: n | U11: n | V11: n | W11: n | X11: =IFERROR((VLOOKUP(R11,Scoring!$A:$B,2,0))+IF(T11="y",1,0)+IF(U11="y",1,0)+IF(V11="y",1,0)+IF(W11="y",1,0),0) -> 1 | Y11: 21 | Z11: 11 | AA11: n | AB11: n | AC11: n | AD11: n | AE11: =IFERROR((VLOOKUP(Y11,Scoring!$A:$B,2,0))+IF(AA11="y",1,0)+IF(AB11="y",1,0)+IF(AC11="y",1,0)+IF(AD11="y",1,0),0) -> 0 | AF11: 13 | AG11: 12 | AH11: n | AI11: n | AJ11: n | AK11: n | AL11: =IFERROR((VLOOKUP(AF11,Scoring!$A:$B,2,0))+IF(AH11="y",1,0)+IF(AI11="y",1,0)+IF(AJ11="y",1,0)+IF(AK11="y",1,0),0) -> 1 | AM11: 11 | AN11: 14 | AO11: n | AP11: n | AQ11: n | AR11: n | AS11: =IFERROR((VLOOKUP(AM11,Scoring!$A:$B,2,0))+IF(AO11="y",1,0)+IF(AP11="y",1,0)+IF(AQ11="y",1,0)+IF(AR11="y",1,0),0) -> 1 | AT11: 10 | AU11: 12 | AV11: n | AW11: n | AX11: n | AY11: n | AZ11: =IFERROR((VLOOKUP(AT11,Scoring!$A:$B,2,0))+IF(AV11="y",1,0)+IF(AW11="y",1,0)+IF(AX11="y",1,0)+IF(AY11="y",1,0),0) -> 2 | BA11: 15 | BB11: 14 | BC11: n | BD11: n | BE11: n | BF11: n | BG11: =IFERROR((VLOOKUP(BA11,Scoring!$D:$E,2,0))+IF(BC11="y",1,0)+IF(BD11="y",1,0)+IF(BE11="y",1,0)+IF(BF11="y",1,0),0) -> 0.5 | BH11: 10 | BI11: 4 | BJ11: n | BK11: n | BL11: n | BM11: n | BN11: =IFERROR((VLOOKUP(BH11,Scoring!$A:$B,2,0))+IF(BJ11="y",1,0)+IF(BK11="y",1,0)+IF(BL11="y",1,0)+IF(BM11="y",1,0),0) -> 2 | BO11: 22 | BP11: 22 | BQ11: n | BR11: n | BS11: n | BT11: n | BU11: =IFERROR((VLOOKUP(BO11,Scoring!$D:$E,2,0))+IF(BQ11="y",1,0)+IF(BR11="y",1,0)+IF(BS11="y",1,0)+IF(BT11="y",1,0),0) -> 0 | BV11: 22 | BW11: 22 | BX11: n | BY11: n | BZ11: n | CA11: n | CB11: =IFERROR((VLOOKUP(BV11,Scoring!$A:$B,2,0))+IF(BX11="y",1,0)+IF(BY11="y",1,0)+IF(BZ11="y",1,0)+IF(CA11="y",1,0),0) -> 0 | CC11: 12 | CD11: 9 | CE11: n | CF11: n | CG11: n | CH11: n | CI11: =IFERROR((VLOOKUP(CC11,Scoring!$A:$B,2,0))+IF(CE11="y",1,0)+IF(CF11="y",1,0)+IF(CG11="y",1,0)+IF(CH11="y",1,0),0) -> 1 | CJ11: 13 | CK11: 12 | CL11: n | CM11: n | CN11: n | CO11: n | CP11: =IFERROR((VLOOKUP(CJ11,Scoring!$A:$B,2,0))+IF(CL11="y",1,0)+IF(CM11="y",1,0)+IF(CN11="y",1,0)+IF(CO11="y",1,0),0) -> 1 | CQ11: 22 | CR11: 22 | CS11: n | CT11: n | CU11: n | CV11: n | CW11: =IFERROR((VLOOKUP(CQ11,Scoring!$A:$B,2,0))+IF(CS11="y",1,0)+IF(CT11="y",1,0)+IF(CU11="y",1,0)+IF(CV11="y",1,0),0) -> 0 | CX11: 22 | CY11: 22 | CZ11: n | DA11: n | DB11: n | DC11: n | DD11: =IFERROR((VLOOKUP(CX11,Scoring!$A:$B,2,0))+IF(CZ11="y",1,0)+IF(DA11="y",1,0)+IF(DB11="y",1,0)+IF(DC11="y",1,0),0) -> 0 | DE11: 9 | DF11: 12 | DG11: n | DH11: n | DI11: n | DJ11: n | DK11: =IFERROR((VLOOKUP(DE11,Scoring!$A:$B,2,0))+IF(DG11="y",1,0)+IF(DH11="y",1,0)+IF(DI11="y",1,0)+IF(DJ11="y",1,0),0) -> 3 | DL11: 14 | DM11: 15 | DN11: n | DO11: n | DP11: n | DQ11: n | DR11: =IFERROR((VLOOKUP(DL11,Scoring!$A:$B,2,0))+IF(DN11="y",1,0)+IF(DO11="y",1,0)+IF(DP11="y",1,0)+IF(DQ11="y",1,0),0) -> 1 | DS11: 0
